Workbook

Sheet LE11_BEHE_HO_P1toP2
S1: Strain and Stress Ranges | U1: BE-HE | AA1: Strain and Stress Ranges | AC1: BE-HE | AI1: Strain and Stress Ranges | AK1: BE-HE
R2: 10in | S2: Max. Axial Mechanical Tensile Strain OD (Hydrotest) | U2: 0.00176536 | V2: checked | W2: x | Z2: 10in | AA2: Max. Axial Mechanical Tensile Strain OD (Hydrotest) | AC2: 0.00106216 | AD2: checked | AE2: x | AH2: 10in | AI2: Max. Axial Mechanical Tensile Strain OD (Hydrotest) | AK2: 0.00029 | AL2: checked | AM2: x
R3: Sleeper | S3: Max. Axial Total Tensile Strain OD (Hydrotest) | U3: 0.00176536 | V3: checked | W3: x | Z3: Structure | AA3: Max. Axial Total Tensile Strain OD (Hydrotest) | AC3: 0.00106216 | AD3: checked | AE3: x | AH3: Other | AI3: Max. Axial Total Tensile Strain OD (Hydrotest) | AK3: 0.00029 | AL3: checked | AM3: x
S4: Max. Axial Mechanical Tensile Strain Midwall (Hydrotest) | U4: 0.00156892 | V4: checked | W4: x | AA4: Max. Axial Mechanical Tensile Strain Midwall (Hydrotest) | AC4: 0.000944744 | AD4: checked | AE4: x | AI4: Max. Axial Mechanical Tensile Strain Midwall (Hydrotest) | AK4: 0.00028 | AL4: checked | AM4: x
S5: Max. Axial Total Tensile Strain Midwall (Hydrotest) | U5: 0.00156892 | V5: checked | W5: x | AA5: Max. Axial Total Tensile Strain Midwall (Hydrotest) | AC5: 0.000944744 | AD5: checked | AE5: x | AI5: Max. Axial Total Tensile Strain Midwall (Hydrotest) | AK5: 0.00028 | AL5: checked | AM5: x
S6: Max. Axial Mechanical Tensile Strain OD (Design) | U6: 0.002417301 | V6: checked | W6: x | AA6: Max. Axial Mechanical Tensile Strain OD (Design) | AC6: 0.001117512 | AD6: checked | AE6: x | AI6: Max. Axial Mechanical Tensile Strain OD (Design) | AK6: 0.00073 | AL6: checked | AM6: x
S7: Max. Axial Total Tensile Strain OD (Design) | U7: 0.00344893 | V7: checked | W7: x | AA7: Max. Axial Total Tensile Strain OD (Design) | AC7: 0.00214876 | AD7: checked | AE7: x | AI7: Max. Axial Total Tensile Strain OD (Design) | AK7: 0.00172 | AL7: checked | AM7: x
S8: Max. Axial Mechanical Tensile Strain Midwall (Design) | U8: 0.002130451 | V8: checked | W8: x | AA8: Max. Axial Mechanical Tensile Strain Midwall (Design) | AC8: 0.000982982 | AD8: checked | AE8: x | AI8: Max. Axial Mechanical Tensile Strain Midwall (Design) | AK8: 0.00065 | AL8: checked | AM8: x
S9: Max. Axial Total Tensile Strain Midwall (Design) | U9: 0.00318003 | V9: checked | W9: x | AA9: Max. Axial Total Tensile Strain Midwall (Design) | AC9: 0.00204296 | AD9: checked | AE9: x | AI9: Max. Axial Total Tensile Strain Midwall (Design) | AK9: 0.00167 | AL9: checked | AM9: x
S10: Max. Axial Mechanical Tensile Strain OD (Early Life) | U10: 0.00211 | V10: checked | W10: x | AA10: Max. Axial Mechanical Tensile Strain OD (Early Life) | AC10: 0.00072 | AD10: checked | AE10: x | AI10: Max. Axial Mechanical Tensile Strain OD (Early Life) | AK10: 0.00018 | AL10: checked | AM10: x
S11: Max. Axial Total Tensile Strain OD (Early Life) | U11: 0.003 | V11: checked | W11: x | AA11: Max. Axial Total Tensile Strain OD (Early Life) | AC11: 0.00113 | AD11: checked | AE11: x | AI11: Max. Axial Total Tensile Strain OD (Early Life) | AK11: 0.001 | AL11: checked | AM11: x
S12: Max. Axial Mechanical Tensile Strain Midwall (Early Life) | U12: 0.00185 | V12: checked | W12: x | AA12: Max. Axial Mechanical Tensile Strain Midwall (Early Life) | AC12: 0.00063 | AD12: checked | AE12: x | AI12: Max. Axial Mechanical Tensile Strain Midwall (Early Life) | AK12: 0.00017 | AL12: checked | AM12: x
S13: Max. Axial Total Tensile Strain Midwall (Early Life) | U13: 0.00274 | V13: checked | W13: x | AA13: Max. Axial Total Tensile Strain Midwall (Early Life) | AC13: 0.00105 | AD13: checked | AE13: x | AI13: Max. Axial Total Tensile Strain Midwall (Early Life) | AK13: 0.00098 | AL13: checked | AM13: x
S14: Max. Axial Mechanical Tensile Strain OD (Mid Life) | U14: 0.00181 | AA14: Max. Axial Mechanical Tensile Strain OD (Mid Life) | AC14: 0.00072 | AI14: Max. Axial Mechanical Tensile Strain OD (Mid Life) | AK14: 0.00018
S15: Max. Axial Total Tensile Strain OD (Mid Life) | U15: 0.00268 | AA15: Max. Axial Total Tensile Strain OD (Mid Life) | AC15: 0.00113 | AI15: Max. Axial Total Tensile Strain OD (Mid Life) | AK15: 0.00099
S16: Max. Axial Mechanical Tensile Strain Midwall (Mid Life) | U16: 0.00158 | AA16: Max. Axial Mechanical Tensile Strain Midwall (Mid Life) | AC16: 0.00064 | AI16: Max. Axial Mechanical Tensile Strain Midwall (Mid Life) | AK16: 0.00016
S17: Max. Axial Total Tensile Strain Midwall (Mid Life) | U17: 0.00245 | AA17: Max. Axial Total Tensile Strain Midwall (Mid Life) | AC17: 0.00105 | AI17: Max. Axial Total Tensile Strain Midwall (Mid Life) | AK17: 0.00097
S18: Max. Axial Mechanical Tensile Strain OD (Late Life) | U18: 0.0018 | V18: checked | W18: x | AA18: Max. Axial Mechanical Tensile Strain OD (Late Life) | AC18: 0.00072 | AD18: checked | AE18: x | AI18: Max. Axial Mechanical Tensile Strain OD (Late Life) | AK18: 0.00018 | AL18: checked | AM18: x
S19: Max. Axial Total Tensile Strain OD (Late Life) | U19: 0.00268 | V19: checked | W19: x | AA19: Max. Axial Total Tensile Strain OD (Late Life) | AC19: 0.00113 | AD19: checked | AE19: x | AI19: Max. Axial Total Tensile Strain OD (Late Life) | AK19: 0.00098 | AL19: checked | AM19: x
S20: Max. Axial Mechanical Tensile Strain Midwall (Late Life) | U20: 0.00157 | V20: checked | W20: x | AA20: Max. Axial Mechanical Tensile Strain Midwall (Late Life) | AC20: 0.00064 | AD20: checked | AE20: x | AI20: Max. Axial Mechanical Tensile Strain Midwall (Late Life) | AK20: 0.00016 | AL20: checked | AM20: x
S21: Max. Axial Total Tensile Strain Midwall (Late Life) | U21: 0.00246 | V21: checked | W21: x | AA21: Max. Axial Total Tensile Strain Midwall (Late Life) | AC21: 0.00105 | AD21: checked | AE21: x | AI21: Max. Axial Total Tensile Strain Midwall (Late Life) | AK21: 0.00096 | AL21: checked | AM21: x
S22: Longitudinal Stress Range at Root, MPa (FCD) | T22: Early Life (1 to 15 yr) | AA22: Longitudinal Stress Range at Root, MPa (FCD) | AB22: Early Life (1 to 15 yr) | AI22: Longitudinal Stress Range at Root, MPa (FCD) | AJ22: Early Life (1 to 15 yr)
T24: Late Life (16 to 25 yr) | AB24: Late Life (16 to 25 yr) | AJ24: Late Life (16 to 25 yr)
S25: Longitudinal Stress Range at Root, MPa (PCD) | T25: Early Life (1 to 15 yr) | AA25: Longitudinal Stress Range at Root, MPa (PCD) | AB25: Early Life (1 to 15 yr) | AI25: Longitudinal Stress Range at Root, MPa (PCD) | AJ25: Early Life (1 to 15 yr)
T27: Late Life (16 to 25 yr) | AB27: Late Life (16 to 25 yr) | AJ27: Late Life (16 to 25 yr)
S28: Longitudinal Stress Range at Root, MPa (Between Hot Oiling) | T28: Early Life (1 to 15 yr) | AA28: Longitudinal Stress Range at Root, MPa (Between Hot Oiling) | AB28: Early Life (1 to 15 yr) | AI28: Longitudinal Stress Range at Root, MPa (Between Hot Oiling) | AJ28: Early Life (1 to 15 yr)
T30: Late Life (16 to 25 yr) | AB30: Late Life (16 to 25 yr) | AJ30: Late Life (16 to 25 yr)
S31: Longitudinal Stress Range at Root (Hydrotest), MPa | AA31: Longitudinal Stress Range at Root (Hydrotest), MPa | AI31: Longitudinal Stress Range at Root (Hydrotest), MPa
S32: Longitudinal Stress Range at Cap, MPa (FCD) | T32: Early Life (1 to 15 yr) | AA32: Longitudinal Stress Range at Cap, MPa (FCD) | AB32: Early Life (1 to 15 yr) | AI32: Longitudinal Stress Range at Cap, MPa (FCD) | AJ32: Early Life (1 to 15 yr)
T34: Late Life (16 to 25 yr) | AB34: Late Life (16 to 25 yr) | AJ34: Late Life (16 to 25 yr)
S35: Longitudinal Stress Range at Cap, MPa (PCD) | T35: Early Life (1 to 15 yr) | AA35: Longitudinal Stress Range at Cap, MPa (PCD) | AB35: Early Life (1 to 15 yr) | AI35: Longitudinal Stress Range at Cap, MPa (PCD) | AJ35: Early Life (1 to 15 yr)
T37: Late Life (16 to 25 yr) | AB37: Late Life (16 to 25 yr) | AJ37: Late Life (16 to 25 yr)
S38: Longitudinal Stress Range at Root, MPa (Between Hot Oiling) | T38: Early Life (1 to 15 yr) | AA38: Longitudinal Stress Range at Root, MPa (Between Hot Oiling) | AB38: Early Life (1 to 15 yr) | AI38: Longitudinal Stress Range at Root, MPa (Between Hot Oiling) | AJ38: Early Life (1 to 15 yr)
T40: Late Life (16 to 25 yr) | AB40: Late Life (16 to 25 yr) | AJ40: Late Life (16 to 25 yr)
S41: Longitudinal Stress Range at CAP (Hydrotest), MPa | AA41: Longitudinal Stress Range at CAP (Hydrotest), MPa | AI41: Longitudinal Stress Range at CAP (Hydrotest), MPa
S44: Strain and Stress Ranges | U44: BE-HE | V44: LE-BE | W44: BE-BE | X44: HE-BE | Y44: Input for ECA | AA44: Strain and Stress Ranges | AC44: BE-HE | AD44: LE-BE | AE44: BE-BE | AF44: HE-BE | AG44: Input for ECA | AI44: Strain and Stress Ranges | AK44: BE-HE | AL44: LE-BE | AM44: BE-BE | AN44: HE-BE | AO44: Input for ECA
R45: 12in | S45: Max. Axial Mechanical Tensile Strain OD (Hydrotest) | U45: 0.00187113 | V45: checked | W45: x | Z45: 12in | AA45: Max. Axial Mechanical Tensile Strain OD (Hydrotest) | AC45: 0.0013 | AD45: checked | AE45: x | AH45: 12in | AI45: Max. Axial Mechanical Tensile Strain OD (Hydrotest) | AK45: 0.00041 | AL45: checked | AM45: x
R46: Sleerper | S46: Max. Axial Total Tensile Strain OD (Hydrotest) | U46: 0.00187113 | V46: checked | W46: x | Z46: Structure | AA46: Max. Axial Total Tensile Strain OD (Hydrotest) | AC46: 0.0013 | AD46: checked | AE46: x | AH46: Other | AI46: Max. Axial Total Tensile Strain OD (Hydrotest) | AK46: 0.00041 | AL46: checked | AM46: x
S47: Max. Axial Mechanical Tensile Strain Midwall (Hydrotest) | U47: 0.00168138 | V47: checked | W47: x | AA47: Max. Axial Mechanical Tensile Strain Midwall (Hydrotest) | AC47: 0.0011 | AD47: checked | AE47: x | AI47: Max. Axial Mechanical Tensile Strain Midwall (Hydrotest) | AK47: 0.00038 | AL47: checked | AM47: x
S48: Max. Axial Total Tensile Strain Midwall (Hydrotest) | U48: 0.00168138 | V48: checked | W48: x | AA48: Max. Axial Total Tensile Strain Midwall (Hydrotest) | AC48: 0.0011 | AD48: checked | AE48: x | AI48: Max. Axial Total Tensile Strain Midwall (Hydrotest) | AK48: 0.00038 | AL48: checked | AM48: x
...

Sheet LE11_BEHE_HO_P2toP1
S1: Strain and Stress Ranges | U1: BE-HE | AA1: Strain and Stress Ranges | AC1: BE-HE | AI1: Strain and Stress Ranges | AK1: BE-HE
R2: 10in | S2: Max. Axial Mechanical Tensile Strain OD (Hydrotest) | U2: 0.00176536 | V2: checked | W2: x | Z2: 10in | AA2: Max. Axial Mechanical Tensile Strain OD (Hydrotest) | AC2: 0.00106216 | AD2: checked | AE2: x | AH2: 10in | AI2: Max. Axial Mechanical Tensile Strain OD (Hydrotest) | AK2: 0.00029 | AL2: checked | AM2: x
R3: Sleeper | S3: Max. Axial Total Tensile Strain OD (Hydrotest) | U3: 0.00176536 | V3: checked | W3: x | Z3: Structure | AA3: Max. Axial Total Tensile Strain OD (Hydrotest) | AC3: 0.00106216 | AD3: checked | AE3: x | AH3: Other | AI3: Max. Axial Total Tensile Strain OD (Hydrotest) | AK3: 0.00029 | AL3: checked | AM3: x
S4: Max. Axial Mechanical Tensile Strain Midwall (Hydrotest) | U4: 0.00156892 | V4: checked | W4: x | AA4: Max. Axial Mechanical Tensile Strain Midwall (Hydrotest) | AC4: 0.000944744 | AD4: checked | AE4: x | AI4: Max. Axial Mechanical Tensile Strain Midwall (Hydrotest) | AK4: 0.00028 | AL4: checked | AM4: x
S5: Max. Axial Total Tensile Strain Midwall (Hydrotest) | U5: 0.00156892 | V5: checked | W5: x | AA5: Max. Axial Total Tensile Strain Midwall (Hydrotest) | AC5: 0.000944744 | AD5: checked | AE5: x | AI5: Max. Axial Total Tensile Strain Midwall (Hydrotest) | AK5: 0.00028 | AL5: checked | AM5: x
S6: Max. Axial Mechanical Tensile Strain OD (Design) | U6: 0.002417301 | V6: checked | W6: x | AA6: Max. Axial Mechanical Tensile Strain OD (Design) | AC6: 0.001117512 | AD6: checked | AE6: x | AI6: Max. Axial Mechanical Tensile Strain OD (Design) | AK6: 0.00073 | AL6: checked | AM6: x
S7: Max. Axial Total Tensile Strain OD (Design) | U7: 0.00344893 | V7: checked | W7: x | AA7: Max. Axial Total Tensile Strain OD (Design) | AC7: 0.00214876 | AD7: checked | AE7: x | AI7: Max. Axial Total Tensile Strain OD (Design) | AK7: 0.00172 | AL7: checked | AM7: x
S8: Max. Axial Mechanical Tensile Strain Midwall (Design) | U8: 0.002130451 | V8: checked | W8: x | AA8: Max. Axial Mechanical Tensile Strain Midwall (Design) | AC8: 0.000982982 | AD8: checked | AE8: x | AI8: Max. Axial Mechanical Tensile Strain Midwall (Design) | AK8: 0.00065 | AL8: checked | AM8: x
S9: Max. Axial Total Tensile Strain Midwall (Design) | U9: 0.00318003 | V9: checked | W9: x | AA9: Max. Axial Total Tensile Strain Midwall (Design) | AC9: 0.00204296 | AD9: checked | AE9: x | AI9: Max. Axial Total Tensile Strain Midwall (Design) | AK9: 0.00167 | AL9: checked | AM9: x
S10: Max. Axial Mechanical Tensile Strain OD (Early Life) | U10: 0.00211 | V10: checked | W10: x | AA10: Max. Axial Mechanical Tensile Strain OD (Early Life) | AC10: 0.00072 | AD10: checked | AE10: x | AI10: Max. Axial Mechanical Tensile Strain OD (Early Life) | AK10: 0.00019 | AL10: checked | AM10: x
S11: Max. Axial Total Tensile Strain OD (Early Life) | U11: 0.003 | V11: checked | W11: x | AA11: Max. Axial Total Tensile Strain OD (Early Life) | AC11: 0.00122 | AD11: checked | AE11: x | AI11: Max. Axial Total Tensile Strain OD (Early Life) | AK11: 0.001 | AL11: checked | AM11: x
S12: Max. Axial Mechanical Tensile Strain Midwall (Early Life) | U12: 0.00185 | V12: checked | W12: x | AA12: Max. Axial Mechanical Tensile Strain Midwall (Early Life) | AC12: 0.00064 | AD12: checked | AE12: x | AI12: Max. Axial Mechanical Tensile Strain Midwall (Early Life) | AK12: 0.00017 | AL12: checked | AM12: x
S13: Max. Axial Total Tensile Strain Midwall (Early Life) | U13: 0.00274 | V13: checked | W13: x | AA13: Max. Axial Total Tensile Strain Midwall (Early Life) | AC13: 0.00114 | AD13: checked | AE13: x | AI13: Max. Axial Total Tensile Strain Midwall (Early Life) | AK13: 0.00098 | AL13: checked | AM13: x
S14: Max. Axial Mechanical Tensile Strain OD (Mid Life) | U14: 0.00184 | V14: checked | W14: x | AA14: Max. Axial Mechanical Tensile Strain OD (Mid Life) | AC14: 0.00072 | AD14: checked | AE14: x | AI14: Max. Axial Mechanical Tensile Strain OD (Mid Life) | AK14: 0.00019 | AL14: checked | AM14: x
S15: Max. Axial Total Tensile Strain OD (Mid Life) | U15: 0.00267 | V15: checked | AA15: Max. Axial Total Tensile Strain OD (Mid Life) | AC15: 0.00121 | AD15: checked | AI15: Max. Axial Total Tensile Strain OD (Mid Life) | AK15: 0.00099 | AL15: checked
S16: Max. Axial Mechanical Tensile Strain Midwall (Mid Life) | U16: 0.00162 | V16: checked | W16: x | AA16: Max. Axial Mechanical Tensile Strain Midwall (Mid Life) | AC16: 0.00064 | AD16: checked | AE16: x | AI16: Max. Axial Mechanical Tensile Strain Midwall (Mid Life) | AK16: 0.00017 | AL16: checked | AM16: x
S17: Max. Axial Total Tensile Strain Midwall (Mid Life) | U17: 0.00245 | V17: checked | AA17: Max. Axial Total Tensile Strain Midwall (Mid Life) | AC17: 0.00113 | AD17: checked | AI17: Max. Axial Total Tensile Strain Midwall (Mid Life) | AK17: 0.00097 | AL17: checked
S18: Max. Axial Mechanical Tensile Strain OD (Late Life) | U18: 0.00181 | V18: checked | W18: x | AA18: Max. Axial Mechanical Tensile Strain OD (Late Life) | AC18: 0.00072 | AD18: checked | AE18: x | AI18: Max. Axial Mechanical Tensile Strain OD (Late Life) | AK18: 0.0002 | AL18: checked | AM18: x
S19: Max. Axial Total Tensile Strain OD (Late Life) | U19: 0.00269 | V19: checked | W19: x | AA19: Max. Axial Total Tensile Strain OD (Late Life) | AC19: 0.00121 | AD19: checked | AE19: x | AI19: Max. Axial Total Tensile Strain OD (Late Life) | AK19: 0.001 | AL19: checked | AM19: x
S20: Max. Axial Mechanical Tensile Strain Midwall (Late Life) | U20: 0.00159 | V20: checked | W20: x | AA20: Max. Axial Mechanical Tensile Strain Midwall (Late Life) | AC20: 0.00064 | AD20: checked | AE20: x | AI20: Max. Axial Mechanical Tensile Strain Midwall (Late Life) | AK20: 0.0002 | AL20: checked | AM20: x
S21: Max. Axial Total Tensile Strain Midwall (Late Life) | U21: 0.00247 | V21: checked | W21: x | AA21: Max. Axial Total Tensile Strain Midwall (Late Life) | AC21: 0.00113 | AD21: checked | AE21: x | AI21: Max. Axial Total Tensile Strain Midwall (Late Life) | AK21: 0.001 | AL21: checked | AM21: x
S22: Longitudinal Stress Range at Root, MPa (FCD) | T22: Early Life (1 to 15 yr) | AA22: Longitudinal Stress Range at Root, MPa (FCD) | AB22: Early Life (1 to 15 yr) | AI22: Longitudinal Stress Range at Root, MPa (FCD) | AJ22: Early Life (1 to 15 yr)
T24: Late Life (16 to 25 yr) | AB24: Late Life (16 to 25 yr) | AJ24: Late Life (16 to 25 yr)
S25: Longitudinal Stress Range at Root, MPa (PCD) | T25: Early Life (1 to 15 yr) | AA25: Longitudinal Stress Range at Root, MPa (PCD) | AB25: Early Life (1 to 15 yr) | AI25: Longitudinal Stress Range at Root, MPa (PCD) | AJ25: Early Life (1 to 15 yr)
T27: Late Life (16 to 25 yr) | AB27: Late Life (16 to 25 yr) | AJ27: Late Life (16 to 25 yr)
S28: Longitudinal Stress Range at Root, MPa (Between Hot Oiling) | T28: Early Life (1 to 15 yr) | AA28: Longitudinal Stress Range at Root, MPa (Between Hot Oiling) | AB28: Early Life (1 to 15 yr) | AI28: Longitudinal Stress Range at Root, MPa (Between Hot Oiling) | AJ28: Early Life (1 to 15 yr)
T30: Late Life (16 to 25 yr) | AB30: Late Life (16 to 25 yr) | AJ30: Late Life (16 to 25 yr)
S31: Longitudinal Stress Range at Root (Hydrotest), MPa | AA31: Longitudinal Stress Range at Root (Hydrotest), MPa | AI31: Longitudinal Stress Range at Root (Hydrotest), MPa
S32: Longitudinal Stress Range at Cap, MPa (FCD) | T32: Early Life (1 to 15 yr) | AA32: Longitudinal Stress Range at Cap, MPa (FCD) | AB32: Early Life (1 to 15 yr) | AI32: Longitudinal Stress Range at Cap, MPa (FCD) | AJ32: Early Life (1 to 15 yr)
T34: Late Life (16 to 25 yr) | AB34: Late Life (16 to 25 yr) | AJ34: Late Life (16 to 25 yr)
S35: Longitudinal Stress Range at Cap, MPa (PCD) | T35: Early Life (1 to 15 yr) | AA35: Longitudinal Stress Range at Cap, MPa (PCD) | AB35: Early Life (1 to 15 yr) | AI35: Longitudinal Stress Range at Cap, MPa (PCD) | AJ35: Early Life (1 to 15 yr)
T37: Late Life (16 to 25 yr) | AB37: Late Life (16 to 25 yr) | AJ37: Late Life (16 to 25 yr)
S38: Longitudinal Stress Range at Root, MPa (Between Hot Oiling) | T38: Early Life (1 to 15 yr) | AA38: Longitudinal Stress Range at Root, MPa (Between Hot Oiling) | AB38: Early Life (1 to 15 yr) | AI38: Longitudinal Stress Range at Root, MPa (Between Hot Oiling) | AJ38: Early Life (1 to 15 yr)
T40: Late Life (16 to 25 yr) | AB40: Late Life (16 to 25 yr) | AJ40: Late Life (16 to 25 yr)
S41: Longitudinal Stress Range at CAP (Hydrotest), MPa | AA41: Longitudinal Stress Range at CAP (Hydrotest), MPa | AI41: Longitudinal Stress Range at CAP (Hydrotest), MPa
S44: Strain and Stress Ranges | U44: BE-HE | V44: LE-BE | W44: BE-BE | X44: HE-BE | Y44: Input for ECA | AA44: Strain and Stress Ranges | AC44: BE-HE | AD44: LE-BE | AE44: BE-BE | AF44: HE-BE | AG44: Input for ECA | AI44: Strain and Stress Ranges | AK44: BE-HE | AL44: LE-BE | AM44: BE-BE | AN44: HE-BE | AO44: Input for ECA
R45: 12in | S45: Max. Axial Mechanical Tensile Strain OD (Hydrotest) | U45: 0.00187113 | V45: checked | W45: x | Z45: 12in | AA45: Max. Axial Mechanical Tensile Strain OD (Hydrotest) | AC45: 0.0013 | AD45: checked | AE45: x | AH45: 12in | AI45: Max. Axial Mechanical Tensile Strain OD (Hydrotest) | AK45: 0.00041 | AL45: checked | AM45: x
R46: Sleerper | S46: Max. Axial Total Tensile Strain OD (Hydrotest) | U46: 0.00187113 | V46: checked | W46: x | Z46: Structure | AA46: Max. Axial Total Tensile Strain OD (Hydrotest) | AC46: 0.0013 | AD46: checked | AE46: x | AH46: Other | AI46: Max. Axial Total Tensile Strain OD (Hydrotest) | AK46: 0.00041 | AL46: checked | AM46: x
S47: Max. Axial Mechanical Tensile Strain Midwall (Hydrotest) | U47: 0.00168138 | V47: checked | W47: x | AA47: Max. Axial Mechanical Tensile Strain Midwall (Hydrotest) | AC47: 0.0011 | AD47: checked | AE47: x | AI47: Max. Axial Mechanical Tensile Strain Midwall (Hydrotest) | AK47: 0.00038 | AL47: checked | AM47: x
S48: Max. Axial Total Tensile Strain Midwall (Hydrotest) | U48: 0.00168138 | V48: checked | W48: x | AA48: Max. Axial Total Tensile Strain Midwall (Hydrotest) | AC48: 0.0011 | AD48: checked | AE48: x | AI48: Max. Axial Total Tensile Strain Midwall (Hydrotest) | AK48: 0.00038 | AL48: checked | AM48: x
...

Sheet LE11_LEBE_HO_P1toP2
S1: Strain and Stress Ranges | U1: LE-BE | AA1: Strain and Stress Ranges | AC1: LE-BE | AI1: Strain and Stress Ranges | AK1: LE-BE
R2: 10in | S2: Max. Axial Mechanical Tensile Strain OD (Hydrotest) | U2: 0.00177298 | V2: checked | W2: x | Z2: 10in | AA2: Max. Axial Mechanical Tensile Strain OD (Hydrotest) | AC2: 0.00110818 | AD2: checked | AE2: x | AH2: 10in | AI2: Max. Axial Mechanical Tensile Strain OD (Hydrotest) | AK2: 0.00110818 | AL2: checked | AM2: x
R3: Sleeper | S3: Max. Axial Total Tensile Strain OD (Hydrotest) | U3: 0.00177298 | V3: checked | W3: x | Z3: Structure | AA3: Max. Axial Total Tensile Strain OD (Hydrotest) | AC3: 0.00110818 | AD3: checked | AE3: x | AH3: Other | AI3: Max. Axial Total Tensile Strain OD (Hydrotest) | AK3: 0.00110818 | AL3: checked | AM3: x
S4: Max. Axial Mechanical Tensile Strain Midwall (Hydrotest) | U4: 0.00163656 | V4: checked | W4: x | AA4: Max. Axial Mechanical Tensile Strain Midwall (Hydrotest) | AC4: 0.000987333 | AD4: checked | AE4: x | AI4: Max. Axial Mechanical Tensile Strain Midwall (Hydrotest) | AK4: 0.000987333 | AL4: checked | AM4: x
S5: Max. Axial Total Tensile Strain Midwall (Hydrotest) | U5: 0.00157642 | V5: checked | W5: x | AA5: Max. Axial Total Tensile Strain Midwall (Hydrotest) | AC5: 0.000987333 | AD5: checked | AE5: x | AI5: Max. Axial Total Tensile Strain Midwall (Hydrotest) | AK5: 0.000987333 | AL5: checked | AM5: x
S6: Max. Axial Mechanical Tensile Strain OD (Design) | U6: 0.00219046 | V6: checked | W6: x | AA6: Max. Axial Mechanical Tensile Strain OD (Design) | AC6: 0.00116062 | AD6: checked | AE6: x | AI6: Max. Axial Mechanical Tensile Strain OD (Design) | AK6: 0.00116062 | AL6: checked | AM6: x
S7: Max. Axial Total Tensile Strain OD (Design) | U7: 0.00323953 | V7: checked | W7: x | AA7: Max. Axial Total Tensile Strain OD (Design) | AC7: 0.00217093 | AD7: checked | AE7: x | AI7: Max. Axial Total Tensile Strain OD (Design) | AK7: 0.00217093 | AL7: checked | AM7: x
S8: Max. Axial Mechanical Tensile Strain Midwall (Design) | U8: 0.00193278 | V8: checked | W8: x | AA8: Max. Axial Mechanical Tensile Strain Midwall (Design) | AC8: 0.00102296 | AD8: checked | AE8: x | AI8: Max. Axial Mechanical Tensile Strain Midwall (Design) | AK8: 0.00102296 | AL8: checked | AM8: x
S9: Max. Axial Total Tensile Strain Midwall (Design) | U9: 0.00299725 | V9: checked | W9: x | AA9: Max. Axial Total Tensile Strain Midwall (Design) | AC9: 0.00206439 | AD9: checked | AE9: x | AI9: Max. Axial Total Tensile Strain Midwall (Design) | AK9: 0.00206439 | AL9: checked | AM9: x
S10: Max. Axial Mechanical Tensile Strain OD (Early Life) | U10: 0.00215 | V10: checked | W10: x | AA10: Max. Axial Mechanical Tensile Strain OD (Early Life) | AC10: 0.0007 | AD10: checked | AE10: x | AI10: Max. Axial Mechanical Tensile Strain OD (Early Life) | AK10: 0.00018 | AL10: checked | AM10: x
S11: Max. Axial Total Tensile Strain OD (Early Life) | U11: 0.00305 | V11: checked | W11: x | AA11: Max. Axial Total Tensile Strain OD (Early Life) | AC11: 0.00114 | AD11: checked | AE11: x | AI11: Max. Axial Total Tensile Strain OD (Early Life) | AK11: 0.001 | AL11: checked | AM11: x
S12: Max. Axial Mechanical Tensile Strain Midwall (Early Life) | U12: 0.00188 | V12: checked | W12: x | AA12: Max. Axial Mechanical Tensile Strain Midwall (Early Life) | AC12: 0.00062 | AD12: checked | AE12: x | AI12: Max. Axial Mechanical Tensile Strain Midwall (Early Life) | AK12: 0.00016 | AL12: checked | AM12: x
S13: Max. Axial Total Tensile Strain Midwall (Early Life) | U13: 0.00278 | V13: checked | W13: x | AA13: Max. Axial Total Tensile Strain Midwall (Early Life) | AC13: 0.00141 | AD13: checked | AE13: x | AI13: Max. Axial Total Tensile Strain Midwall (Early Life) | AK13: 0.00098 | AL13: checked | AM13: x
S14: Max. Axial Mechanical Tensile Strain OD (Mid Life) | U14: 0.00178 | V14: checked | W14: x | AA14: Max. Axial Mechanical Tensile Strain OD (Mid Life) | AC14: 0.0007 | AD14: checked | AE14: x | AI14: Max. Axial Mechanical Tensile Strain OD (Mid Life) | AK14: 0.00018 | AL14: checked | AM14: x
S15: Max. Axial Total Tensile Strain OD (Mid Life) | U15: 0.00265 | V15: checked | W15: x | AA15: Max. Axial Total Tensile Strain OD (Mid Life) | AC15: 0.00114 | AD15: checked | AE15: x | AI15: Max. Axial Total Tensile Strain OD (Mid Life) | AK15: 0.00098 | AL15: checked | AM15: x
... S21: Max. Axial Total Tensile Strain Midwall (Late Life) | U21: 0.00242 | V21: checked | W21: x | AA21: Max. Axial Total Tensile Strain Midwall (Late Life) | AC21: 0.00106 | AD21: checked | AE21: x | AI21: Max. Axial Total Tensile Strain Midwall (Late Life) | AK21: 0.00095 | AL21: checked | AM21: x
S22: Longitudinal Stress Range at Root, MPa (FCD) | T22: Early Life (1 to 15 yr) | AA22: Longitudinal Stress Range at Root, MPa (FCD) | AB22: Early Life (1 to 15 yr) | AI22: Longitudinal Stress Range at Root, MPa (FCD) | AJ22: Early Life (1 to 15 yr)
T24: Late Life (16 to 25 yr) | AB24: Late Life (16 to 25 yr) | AJ24: Late Life (16 to 25 yr)
S25: Longitudinal Stress Range at Root, MPa (PCD) | T25: Early Life (1 to 15 yr) | AA25: Longitudinal Stress Range at Root, MPa (PCD) | AB25: Early Life (1 to 15 yr) | AI25: Longitudinal Stress Range at Root, MPa (PCD) | AJ25: Early Life (1 to 15 yr)
T27: Late Life (16 to 25 yr) | AB27: Late Life (16 to 25 yr) | AJ27: Late Life (16 to 25 yr)
S28: Longitudinal Stress Range at Root, MPa (Between Hot Oiling) | T28: Early Life (1 to 15 yr) | AA28: Longitudinal Stress Range at Root, MPa (Between Hot Oiling) | AB28: Early Life (1 to 15 yr) | AI28: Longitudinal Stress Range at Root, MPa (Between Hot Oiling) | AJ28: Early Life (1 to 15 yr)
T30: Late Life (16 to 25 yr) | AB30: Late Life (16 to 25 yr) | AJ30: Late Life (16 to 25 yr)
S31: Longitudinal Stress Range at Root (Hydrotest), MPa | AA31: Longitudinal Stress Range at Root (Hydrotest), MPa | AI31: Longitudinal Stress Range at Root (Hydrotest), MPa
S32: Longitudinal Stress Range at Cap, MPa (FCD) | T32: Early Life (1 to 15 yr) | AA32: Longitudinal Stress Range at Cap, MPa (FCD) | AB32: Early Life (1 to 15 yr) | AI32: Longitudinal Stress Range at Cap, MPa (FCD) | AJ32: Early Life (1 to 15 yr)
T34: Late Life (16 to 25 yr) | AB34: Late Life (16 to 25 yr) | AJ34: Late Life (16 to 25 yr)
S35: Longitudinal Stress Range at Cap, MPa (PCD) | T35: Early Life (1 to 15 yr) | AA35: Longitudinal Stress Range at Cap, MPa (PCD) | AB35: Early Life (1 to 15 yr) | AI35: Longitudinal Stress Range at Cap, MPa (PCD) | AJ35: Early Life (1 to 15 yr)
T37: Late Life (16 to 25 yr) | AB37: Late Life (16 to 25 yr) | AJ37: Late Life (16 to 25 yr)
S38: Longitudinal Stress Range at Root, MPa (Between Hot Oiling) | T38: Early Life (1 to 15 yr) | AA38: Longitudinal Stress Range at Root, MPa (Between Hot Oiling) | AB38: Early Life (1 to 15 yr) | AI38: Longitudinal Stress Range at Root, MPa (Between Hot Oiling) | AJ38: Early Life (1 to 15 yr)
T40: Late Life (16 to 25 yr) | AB40: Late Life (16 to 25 yr) | AJ40: Late Life (16 to 25 yr)
S41: Longitudinal Stress Range at CAP (Hydrotest), MPa | AA41: Longitudinal Stress Range at CAP (Hydrotest), MPa | AI41: Longitudinal Stress Range at CAP (Hydrotest), MPa
S44: Strain and Stress Ranges | U44: LE-BE | V44: LE-BE | W44: BE-BE | X44: HE-BE | Y44: Input for ECA | AA44: Strain and Stress Ranges | AC44: LE-BE | AD44: LE-BE | AE44: BE-BE | AF44: HE-BE | AG44: Input for ECA | AI44: Strain and Stress Ranges | AK44: LE-BE | AL44: LE-BE | AM44: BE-BE | AN44: HE-BE | AO44: Input for ECA
R45: 12in | S45: Max. Axial Mechanical Tensile Strain OD (Hydrotest) | U45: 0.00182003 | V45: checked | W45: x | Z45: 12in | AA45: Max. Axial Mechanical Tensile Strain OD (Hydrotest) | AC45: 0.00130132 | AD45: checked | AE45: x | AH45: 12in | AI45: Max. Axial Mechanical Tensile Strain OD (Hydrotest) | AK45: 0.00130132 | AL45: checked | AM45: x
R46: Sleeper | S46: Max. Axial Total Tensile Strain OD (Hydrotest) | U46: 0.00182003 | V46: checked | W46: x | Z46: Structure | AA46: Max. Axial Total Tensile Strain OD (Hydrotest) | AC46: 0.00130132 | AD46: checked | AE46: x | AH46: Other | AI46: Max. Axial Total Tensile Strain OD (Hydrotest) | AK46: 0.00130132 | AL46: checked | AM46: x
S47: Max. Axial Mechanical Tensile Strain Midwall (Hydrotest) | U47: 0.00163656 | V47: checked | W47: x | AA47: Max. Axial Mechanical Tensile Strain Midwall (Hydrotest) | AC47: 0.00117225 | AD47: checked | AE47: x | AI47: Max. Axial Mechanical Tensile Strain Midwall (Hydrotest) | AK47: 0.00117225 | AL47: checked | AM47: x
S48: Max. Axial Total Tensile Strain Midwall (Hydrotest) | U48: 0.00163656 | V48: checked | W48: x | AA48: Max. Axial Total Tensile Strain Midwall (Hydrotest) | AC48: 0.00117225 | AD48: checked | AE48: x | AI48: Max. Axial Total Tensile Strain Midwall (Hydrotest) | AK48: 0.00117225 | AL48: checked | AM48: x
S49: Max. Axial Mechanical Tensile Strain OD (Design) | U49: 0.00224924 | V49: checked | W49: x | AA49: Max. Axial Mechanical Tensile Strain OD (Design) | AC49: 0.00129924 | AD49: checked | AE49: x | AI49: Max. Axial Mechanical Tensile Strain OD (Design) | AK49: 0.00129924 | AL49: checked | AM49: x
S50: Max. Axial Total Tensile Strain OD (Design) | U50: 0.0034191 | V50: checked | W50: x | AA50: Max. Axial Total Tensile Strain OD (Design) | AC50: 0.0024691 | AD50: checked | AE50: x | AI50: Max. Axial Total Tensile Strain OD (Design) | AK50: 0.0024691 | AL50: checked | AM50: x
S51: Max. Axial Mechanical Tensile Strain Midwall (Design) | U51: 0.00200698 | V51: checked | W51: x | AA51: Max. Axial Mechanical Tensile Strain Midwall (Design) | AC51: 0.00116091 | AD51: checked | AE51: x | AI51: Max. Axial Mechanical Tensile Strain Midwall (Design) | AK51: 0.00116091 | AL51: checked | AM51: x
S52: Max. Axial Total Tensile Strain Midwall (Design) | U52: 0.00317684 | V52: checked | W52: x | AA52: Max. Axial Total Tensile Strain Midwall (Design) | AC52: 0.00233077 | AD52: checked | AE52: x | AI52: Max. Axial Total Tensile Strain Midwall (Design) | AK52: 0.00233077 | AL52: checked | AM52: x
S53: Max. Axial Mechanical Tensile Strain OD (Early Life) | U53: 0.0023 | V53: checked | W53: x | AA53: Max. Axial Mechanical Tensile Strain OD (Early Life) | AC53: 0.00077 | AD53: checked | AE53: x | AI53: Max. Axial Mechanical Tensile Strain OD (Early Life) | AK53: 0.00024 | AL53: checked | AM53: x
...

Sheet LE11_LEBE_HO_P2toP1
S1: Strain and Stress Ranges | U1: LE-BE | AA1: Strain and Stress Ranges | AC1: LE-BE | AI1: Strain and Stress Ranges | AK1: LE-BE
R2: 10in | S2: Max. Axial Mechanical Tensile Strain OD (Hydrotest) | U2: 0.00177298 | V2: checked | W2: x | Z2: 10in | AA2: Max. Axial Mechanical Tensile Strain OD (Hydrotest) | AC2: 0.00110818 | AD2: checked | AE2: x | AH2: 10in | AI2: Max. Axial Mechanical Tensile Strain OD (Hydrotest) | AK2: 0.00110818 | AL2: checked | AM2: x
R3: Sleeper | S3: Max. Axial Total Tensile Strain OD (Hydrotest) | U3: 0.00177298 | V3: checked | W3: x | Z3: Structure | AA3: Max. Axial Total Tensile Strain OD (Hydrotest) | AC3: 0.00110818 | AD3: checked | AE3: x | AH3: Other | AI3: Max. Axial Total Tensile Strain OD (Hydrotest) | AK3: 0.00110818 | AL3: checked | AM3: x
S4: Max. Axial Mechanical Tensile Strain Midwall (Hydrotest) | U4: 0.00163656 | V4: checked | W4: x | AA4: Max. Axial Mechanical Tensile Strain Midwall (Hydrotest) | AC4: 0.000987333 | AD4: checked | AE4: x | AI4: Max. Axial Mechanical Tensile Strain Midwall (Hydrotest) | AK4: 0.000987333 | AL4: checked | AM4: x
S5: Max. Axial Total Tensile Strain Midwall (Hydrotest) | U5: 0.00157642 | V5: checked | W5: x | AA5: Max. Axial Total Tensile Strain Midwall (Hydrotest) | AC5: 0.000987333 | AD5: checked | AE5: x | AI5: Max. Axial Total Tensile Strain Midwall (Hydrotest) | AK5: 0.000987333 | AL5: checked | AM5: x
S6: Max. Axial Mechanical Tensile Strain OD (Design) | U6: 0.00219046 | V6: checked | W6: x | AA6: Max. Axial Mechanical Tensile Strain OD (Design) | AC6: 0.00116062 | AD6: checked | AE6: x | AI6: Max. Axial Mechanical Tensile Strain OD (Design) | AK6: 0.00116062 | AL6: checked | AM6: x
S7: Max. Axial Total Tensile Strain OD (Design) | U7: 0.00323953 | V7: checked | W7: x | AA7: Max. Axial Total Tensile Strain OD (Design) | AC7: 0.00217093 | AD7: checked | AE7: x | AI7: Max. Axial Total Tensile Strain OD (Design) | AK7: 0.00217093 | AL7: checked | AM7: x
S8: Max. Axial Mechanical Tensile Strain Midwall (Design) | U8: 0.00193278 | V8: checked | W8: x | AA8: Max. Axial Mechanical Tensile Strain Midwall (Design) | AC8: 0.00102296 | AD8: checked | AE8: x | AI8: Max. Axial Mechanical Tensile Strain Midwall (Design) | AK8: 0.00102296 | AL8: checked | AM8: x
S9: Max. Axial Total Tensile Strain Midwall (Design) | U9: 0.00299725 | V9: checked | W9: x | AA9: Max. Axial Total Tensile Strain Midwall (Design) | AC9: 0.00206439 | AD9: checked | AE9: x | AI9: Max. Axial Total Tensile Strain Midwall (Design) | AK9: 0.00206439 | AL9: checked | AM9: x
S10: Max. Axial Mechanical Tensile Strain OD (Early Life) | U10: 0.00224 | V10: checked | W10: x | AA10: Max. Axial Mechanical Tensile Strain OD (Early Life) | AC10: 0.0007 | AD10: checked | AE10: x | AI10: Max. Axial Mechanical Tensile Strain OD (Early Life) | AK10: 0.00018 | AL10: checked | AM10: x
S11: Max. Axial Total Tensile Strain OD (Early Life) | U11: 0.00305 | V11: checked | W11: x | AA11: Max. Axial Total Tensile Strain OD (Early Life) | AC11: 0.00123 | AD11: checked | AE11: x | AI11: Max. Axial Total Tensile Strain OD (Early Life) | AK11: 0.001 | AL11: checked | AM11: x
S12: Max. Axial Mechanical Tensile Strain Midwall (Early Life) | U12: 0.00196 | V12: checked | W12: x | AA12: Max. Axial Mechanical Tensile Strain Midwall (Early Life) | AC12: 0.00062 | AD12: checked | AE12: x | AI12: Max. Axial Mechanical Tensile Strain Midwall (Early Life) | AK12: 0.00016 | AL12: checked | AM12: x
S13: Max. Axial Total Tensile Strain Midwall (Early Life) | U13: 0.00278 | V13: checked | W13: x | AA13: Max. Axial Total Tensile Strain Midwall (Early Life) | AC13: 0.00141 | AD13: checked | AE13: x | AI13: Max. Axial Total Tensile Strain Midwall (Early Life) | AK13: 0.00098 | AL13: checked | AM13: x
S14: Max. Axial Mechanical Tensile Strain OD (Mid Life) | U14: 0.00175 | V14: checked | W14: x | AA14: Max. Axial Mechanical Tensile Strain OD (Mid Life) | AC14: 0.0007 | AD14: checked | AE14: x | AI14: Max. Axial Mechanical Tensile Strain OD (Mid Life) | AK14: 0.00019 | AL14: checked | AM14: x
S15: Max. Axial Total Tensile Strain OD (Mid Life) | U15: 0.00256 | V15: checked | W15: x | AA15: Max. Axial Total Tensile Strain OD (Mid Life) | AC15: 0.00122 | AD15: checked | AE15: x | AI15: Max. Axial Total Tensile Strain OD (Mid Life) | AK15: 0.00099 | AL15: checked | AM15: x
... S21: Max. Axial Total Tensile Strain Midwall (Late Life) | U21: 0.00235 | V21: checked | W21: x | AA21: Max. Axial Total Tensile Strain Midwall (Late Life) | AC21: 0.00114 | AD21: checked | AE21: x | AI21: Max. Axial Total Tensile Strain Midwall (Late Life) | AK21: 0.00097 | AL21: checked | AM21: x
S22: Longitudinal Stress Range at Root, MPa (FCD) | T22: Early Life (1 to 15 yr) | AA22: Longitudinal Stress Range at Root, MPa (FCD) | AB22: Early Life (1 to 15 yr) | AI22: Longitudinal Stress Range at Root, MPa (FCD) | AJ22: Early Life (1 to 15 yr)
T24: Late Life (16 to 25 yr) | AB24: Late Life (16 to 25 yr) | AJ24: Late Life (16 to 25 yr)
S25: Longitudinal Stress Range at Root, MPa (PCD) | T25: Early Life (1 to 15 yr) | AA25: Longitudinal Stress Range at Root, MPa (PCD) | AB25: Early Life (1 to 15 yr) | AI25: Longitudinal Stress Range at Root, MPa (PCD) | AJ25: Early Life (1 to 15 yr)
T27: Late Life (16 to 25 yr) | AB27: Late Life (16 to 25 yr) | AJ27: Late Life (16 to 25 yr)
S28: Longitudinal Stress Range at Root, MPa (Between Hot Oiling) | T28: Early Life (1 to 15 yr) | AA28: Longitudinal Stress Range at Root, MPa (Between Hot Oiling) | AB28: Early Life (1 to 15 yr) | AI28: Longitudinal Stress Range at Root, MPa (Between Hot Oiling) | AJ28: Early Life (1 to 15 yr)
T30: Late Life (16 to 25 yr) | AB30: Late Life (16 to 25 yr) | AJ30: Late Life (16 to 25 yr)
S31: Longitudinal Stress Range at Root (Hydrotest), MPa | AA31: Longitudinal Stress Range at Root (Hydrotest), MPa | AI31: Longitudinal Stress Range at Root (Hydrotest), MPa
S32: Longitudinal Stress Range at Cap, MPa (FCD) | T32: Early Life (1 to 15 yr) | AA32: Longitudinal Stress Range at Cap, MPa (FCD) | AB32: Early Life (1 to 15 yr) | AI32: Longitudinal Stress Range at Cap, MPa (FCD) | AJ32: Early Life (1 to 15 yr)
T34: Late Life (16 to 25 yr) | AB34: Late Life (16 to 25 yr) | AJ34: Late Life (16 to 25 yr)
S35: Longitudinal Stress Range at Cap, MPa (PCD) | T35: Early Life (1 to 15 yr) | AA35: Longitudinal Stress Range at Cap, MPa (PCD) | AB35: Early Life (1 to 15 yr) | AI35: Longitudinal Stress Range at Cap, MPa (PCD) | AJ35: Early Life (1 to 15 yr)
T37: Late Life (16 to 25 yr) | AB37: Late Life (16 to 25 yr) | AJ37: Late Life (16 to 25 yr)
S38: Longitudinal Stress Range at Root, MPa (Between Hot Oiling) | T38: Early Life (1 to 15 yr) | AA38: Longitudinal Stress Range at Root, MPa (Between Hot Oiling) | AB38: Early Life (1 to 15 yr) | AI38: Longitudinal Stress Range at Root, MPa (Between Hot Oiling) | AJ38: Early Life (1 to 15 yr)
T40: Late Life (16 to 25 yr) | AB40: Late Life (16 to 25 yr) | AJ40: Late Life (16 to 25 yr)
S41: Longitudinal Stress Range at CAP (Hydrotest), MPa | AA41: Longitudinal Stress Range at CAP (Hydrotest), MPa | AI41: Longitudinal Stress Range at CAP (Hydrotest), MPa
S44: Strain and Stress Ranges | U44: LE-BE | V44: LE-BE | W44: BE-BE | X44: HE-BE | Y44: Input for ECA | AA44: Strain and Stress Ranges | AC44: LE-BE | AD44: LE-BE | AE44: BE-BE | AF44: HE-BE | AG44: Input for ECA | AI44: Strain and Stress Ranges | AK44: LE-BE | AL44: LE-BE | AM44: BE-BE | AN44: HE-BE | AO44: Input for ECA
R45: 12in | S45: Max. Axial Mechanical Tensile Strain OD (Hydrotest) | U45: 0.00182003 | V45: checked | W45: x | Z45: 12in | AA45: Max. Axial Mechanical Tensile Strain OD (Hydrotest) | AC45: 0.00130132 | AD45: checked | AE45: x | AH45: 12in | AI45: Max. Axial Mechanical Tensile Strain OD (Hydrotest) | AK45: 0.00130132 | AL45: checked | AM45: x
R46: Sleeper | S46: Max. Axial Total Tensile Strain OD (Hydrotest) | U46: 0.00182003 | V46: checked | W46: x | Z46: Structure | AA46: Max. Axial Total Tensile Strain OD (Hydrotest) | AC46: 0.00130132 | AD46: checked | AE46: x | AH46: Other | AI46: Max. Axial Total Tensile Strain OD (Hydrotest) | AK46: 0.00130132 | AL46: checked | AM46: x
S47: Max. Axial Mechanical Tensile Strain Midwall (Hydrotest) | U47: 0.00163656 | V47: checked | W47: x | AA47: Max. Axial Mechanical Tensile Strain Midwall (Hydrotest) | AC47: 0.00117225 | AD47: checked | AE47: x | AI47: Max. Axial Mechanical Tensile Strain Midwall (Hydrotest) | AK47: 0.00117225 | AL47: checked | AM47: x
S48: Max. Axial Total Tensile Strain Midwall (Hydrotest) | U48: 0.00163656 | V48: checked | W48: x | AA48: Max. Axial Total Tensile Strain Midwall (Hydrotest) | AC48: 0.00117225 | AD48: checked | AE48: x | AI48: Max. Axial Total Tensile Strain Midwall (Hydrotest) | AK48: 0.00117225 | AL48: checked | AM48: x
S49: Max. Axial Mechanical Tensile Strain OD (Design) | U49: 0.00224924 | V49: checked | W49: x | AA49: Max. Axial Mechanical Tensile Strain OD (Design) | AC49: 0.00129924 | AD49: checked | AE49: x | AI49: Max. Axial Mechanical Tensile Strain OD (Design) | AK49: 0.00129924 | AL49: checked | AM49: x
S50: Max. Axial Total Tensile Strain OD (Design) | U50: 0.0034191 | V50: checked | W50: x | AA50: Max. Axial Total Tensile Strain OD (Design) | AC50: 0.0024691 | AD50: checked | AE50: x | AI50: Max. Axial Total Tensile Strain OD (Design) | AK50: 0.0024691 | AL50: checked | AM50: x
S51: Max. Axial Mechanical Tensile Strain Midwall (Design) | U51: 0.00200698 | V51: checked | W51: x | AA51: Max. Axial Mechanical Tensile Strain Midwall (Design) | AC51: 0.00116091 | AD51: checked | AE51: x | AI51: Max. Axial Mechanical Tensile Strain Midwall (Design) | AK51: 0.00116091 | AL51: checked | AM51: x
S52: Max. Axial Total Tensile Strain Midwall (Design) | U52: 0.00317684 | V52: checked | W52: x | AA52: Max. Axial Total Tensile Strain Midwall (Design) | AC52: 0.00233077 | AD52: checked | AE52: x | AI52: Max. Axial Total Tensile Strain Midwall (Design) | AK52: 0.00233077 | AL52: checked | AM52: x
S53: Max. Axial Mechanical Tensile Strain OD (Early Life) | U53: 0.00228 | V53: checked | W53: x | AA53: Max. Axial Mechanical Tensile Strain OD (Early Life) | AC53: 0.00077 | AD53: checked | AE53: x | AI53: Max. Axial Mechanical Tensile Strain OD (Early Life) | AK53: 0.00021 | AL53: checked | AM53: x
...

Sheet LE11_BEBE_HO_P1toP2
S1: Strain and Stress Ranges | U1: BE-BE | AA1: Strain and Stress Ranges | AC1: BE-BE | AI1: Strain and Stress Ranges | AK1: BE-BE
R2: 10in | S2: Max. Axial Mechanical Tensile Strain OD (Hydrotest) | U2: 0.00170501 | V2: checked | W2: x | Z2: 10in | AA2: Max. Axial Mechanical Tensile Strain OD (Hydrotest) | AC2: 0.00107281 | AD2: checked | AE2: x | AH2: 10in | AI2: Max. Axial Mechanical Tensile Strain OD (Hydrotest) | AK2: 0.00029 | AL2: checked | AM2: x
R3: Sleeper | S3: Max. Axial Total Tensile Strain OD (Hydrotest) | U3: 0.00170501 | V3: checked | W3: x | Z3: Structure | AA3: Max. Axial Total Tensile Strain OD (Hydrotest) | AC3: 0.00107281 | AD3: checked | AE3: x | AH3: Other | AI3: Max. Axial Total Tensile Strain OD (Hydrotest) | AK3: 0.00029 | AL3: checked | AM3: x
S4: Max. Axial Mechanical Tensile Strain Midwall (Hydrotest) | U4: 0.00151641 | V4: checked | W4: x | AA4: Max. Axial Mechanical Tensile Strain Midwall (Hydrotest) | AC4: 0.000954594 | AD4: checked | AE4: x | AI4: Max. Axial Mechanical Tensile Strain Midwall (Hydrotest) | AK4: 0.00028 | AL4: checked | AM4: x
S5: Max. Axial Total Tensile Strain Midwall (Hydrotest) | U5: 0.00151641 | V5: checked | W5: x | AA5: Max. Axial Total Tensile Strain Midwall (Hydrotest) | AC5: 0.000954594 | AD5: checked | AE5: x | AI5: Max. Axial Total Tensile Strain Midwall (Hydrotest) | AK5: 0.00028 | AL5: checked | AM5: x
S6: Max. Axial Mechanical Tensile Strain OD (Design) | U6: 0.002153191 | V6: checked | W6: x | AA6: Max. Axial Mechanical Tensile Strain OD (Design) | AC6: 0.001129412 | AD6: checked | AE6: x | AI6: Max. Axial Mechanical Tensile Strain OD (Design) | AK6: 0.0009 | AL6: checked | AM6: x
S7: Max. Axial Total Tensile Strain OD (Design) | U7: 0.00319258 | V7: checked | W7: x | AA7: Max. Axial Total Tensile Strain OD (Design) | AC7: 0.00215488 | AD7: checked | AE7: x | AI7: Max. Axial Total Tensile Strain OD (Design) | AK7: 0.0019 | AL7: checked | AM7: x
S8: Max. Axial Mechanical Tensile Strain Midwall (Design) | U8: 0.001900061 | V8: checked | W8: x | AA8: Max. Axial Mechanical Tensile Strain Midwall (Design) | AC8: 0.000994022 | AD8: checked | AE8: x | AI8: Max. Axial Mechanical Tensile Strain Midwall (Design) | AK8: 0.0008 | AL8: checked | AM8: x
S9: Max. Axial Total Tensile Strain Midwall (Design) | U9: 0.0029559 | V9: checked | W9: x | AA9: Max. Axial Total Tensile Strain Midwall (Design) | AC9: 0.00204887 | AD9: checked | AE9: x | AI9: Max. Axial Total Tensile Strain Midwall (Design) | AK9: 0.0018 | AL9: checked | AM9: x
S10: Max. Axial Mechanical Tensile Strain OD (Early Life) | U10: 0.00196 | V10: checked | W10: x | AA10: Max. Axial Mechanical Tensile Strain OD (Early Life) | AC10: 0.00072 | AD10: checked | AE10: x | AI10: Max. Axial Mechanical Tensile Strain OD (Early Life) | AK10: 0.00018 | AL10: checked | AM10: x
S11: Max. Axial Total Tensile Strain OD (Early Life) | U11: 0.00285 | V11: checked | W11: x | AA11: Max. Axial Total Tensile Strain OD (Early Life) | AC11: 0.00114 | AD11: checked | AE11: x | AI11: Max. Axial Total Tensile Strain OD (Early Life) | AK11: 0.001 | AL11: checked | AM11: x
S12: Max. Axial Mechanical Tensile Strain Midwall (Early Life) | U12: 0.00172 | V12: checked | W12: x | AA12: Max. Axial Mechanical Tensile Strain Midwall (Early Life) | AC12: 0.00064 | AD12: checked | AE12: x | AI12: Max. Axial Mechanical Tensile Strain Midwall (Early Life) | AK12: 0.00016 | AL12: checked | AM12: x
S13: Max. Axial Total Tensile Strain Midwall (Early Life) | U13: 0.00261 | V13: checked | W13: x | AA13: Max. Axial Total Tensile Strain Midwall (Early Life) | AC13: 0.00105 | AD13: checked | AE13: x | AI13: Max. Axial Total Tensile Strain Midwall (Early Life) | AK13: 0.00098 | AL13: checked | AM13: x
S14: Max. Axial Mechanical Tensile Strain OD (Mid Life) | U14: 0.00166 | AA14: Max. Axial Mechanical Tensile Strain OD (Mid Life) | AC14: 0.00072 | AI14: Max. Axial Mechanical Tensile Strain OD (Mid Life) | AK14: 0.00018
S15: Max. Axial Total Tensile Strain OD (Mid Life) | U15: 0.00253 | AA15: Max. Axial Total Tensile Strain OD (Mid Life) | AC15: 0.00113 | AI15: Max. Axial Total Tensile Strain OD (Mid Life) | AK15: 0.00101
S16: Max. Axial Mechanical Tensile Strain Midwall (Mid Life) | U16: 0.00146 | AA16: Max. Axial Mechanical Tensile Strain Midwall (Mid Life) | AC16: 0.00064 | AI16: Max. Axial Mechanical Tensile Strain Midwall (Mid Life) | AK16: 0.00016
S17: Max. Axial Total Tensile Strain Midwall (Mid Life) | U17: 0.00233 | AA17: Max. Axial Total Tensile Strain Midwall (Mid Life) | AC17: 0.00105 | AI17: Max. Axial Total Tensile Strain Midwall (Mid Life) | AK17: 0.00099
S18: Max. Axial Mechanical Tensile Strain OD (Late Life) | U18: 0.0017 | V18: checked | W18: x | AA18: Max. Axial Mechanical Tensile Strain OD (Late Life) | AC18: 0.00072 | AD18: checked | AE18: x | AI18: Max. Axial Mechanical Tensile Strain OD (Late Life) | AK18: 0.00018 | AL18: checked | AM18: x
S19: Max. Axial Total Tensile Strain OD (Late Life) | U19: 0.00255 | V19: checked | W19: x | AA19: Max. Axial Total Tensile Strain OD (Late Life) | AC19: 0.00113 | AD19: checked | AE19: x | AI19: Max. Axial Total Tensile Strain OD (Late Life) | AK19: 0.00101 | AL19: checked | AM19: x
S20: Max. Axial Mechanical Tensile Strain Midwall (Late Life) | U20: 0.00148 | V20: checked | W20: x | AA20: Max. Axial Mechanical Tensile Strain Midwall (Late Life) | AC20: 0.00064 | AD20: checked | AE20: x | AI20: Max. Axial Mechanical Tensile Strain Midwall (Late Life) | AK20: 0.00017 | AL20: checked | AM20: x
S21: Max. Axial Total Tensile Strain Midwall (Late Life) | U21: 0.00234 | V21: checked | W21: x | AA21: Max. Axial Total Tensile Strain Midwall (Late Life) | AC21: 0.00105 | AD21: checked | AE21: x | AI21: Max. Axial Total Tensile Strain Midwall (Late Life) | AK21: 0.00099 | AL21: checked | AM21: x
S22: Longitudinal Stress Range at Root, MPa (FCD) | T22: Early Life (1 to 15 yr) | AA22: Longitudinal Stress Range at Root, MPa (FCD) | AB22: Early Life (1 to 15 yr) | AI22: Longitudinal Stress Range at Root, MPa (FCD) | AJ22: Early Life (1 to 15 yr)
T24: Late Life (16 to 25 yr) | AB24: Late Life (16 to 25 yr) | AJ24: Late Life (16 to 25 yr)
S25: Longitudinal Stress Range at Root, MPa (PCD) | T25: Early Life (1 to 15 yr) | AA25: Longitudinal Stress Range at Root, MPa (PCD) | AB25: Early Life (1 to 15 yr) | AI25: Longitudinal Stress Range at Root, MPa (PCD) | AJ25: Early Life (1 to 15 yr)
T27: Late Life (16 to 25 yr) | AB27: Late Life (16 to 25 yr) | AJ27: Late Life (16 to 25 yr)
S28: Longitudinal Stress Range at Root, MPa (Between Hot Oiling) | T28: Early Life (1 to 15 yr) | AA28: Longitudinal Stress Range at Root, MPa (Between Hot Oiling) | AB28: Early Life (1 to 15 yr) | AI28: Longitudinal Stress Range at Root, MPa (Between Hot Oiling) | AJ28: Early Life (1 to 15 yr)
T30: Late Life (16 to 25 yr) | AB30: Late Life (16 to 25 yr) | AJ30: Late Life (16 to 25 yr)
S31: Longitudinal Stress Range at Root (Hydrotest), MPa | AA31: Longitudinal Stress Range at Root (Hydrotest), MPa | AI31: Longitudinal Stress Range at Root (Hydrotest), MPa
S32: Longitudinal Stress Range at Cap, MPa (FCD) | T32: Early Life (1 to 15 yr) | AA32: Longitudinal Stress Range at Cap, MPa (FCD) | AB32: Early Life (1 to 15 yr) | AI32: Longitudinal Stress Range at Cap, MPa (FCD) | AJ32: Early Life (1 to 15 yr)
T34: Late Life (16 to 25 yr) | AB34: Late Life (16 to 25 yr) | AJ34: Late Life (16 to 25 yr)
S35: Longitudinal Stress Range at Cap, MPa (PCD) | T35: Early Life (1 to 15 yr) | AA35: Longitudinal Stress Range at Cap, MPa (PCD) | AB35: Early Life (1 to 15 yr) | AI35: Longitudinal Stress Range at Cap, MPa (PCD) | AJ35: Early Life (1 to 15 yr)
T37: Late Life (16 to 25 yr) | AB37: Late Life (16 to 25 yr) | AJ37: Late Life (16 to 25 yr)
S38: Longitudinal Stress Range at Root, MPa (Between Hot Oiling) | T38: Early Life (1 to 15 yr) | AA38: Longitudinal Stress Range at Root, MPa (Between Hot Oiling) | AB38: Early Life (1 to 15 yr) | AI38: Longitudinal Stress Range at Root, MPa (Between Hot Oiling) | AJ38: Early Life (1 to 15 yr)
T40: Late Life (16 to 25 yr) | AB40: Late Life (16 to 25 yr) | AJ40: Late Life (16 to 25 yr)
S41: Longitudinal Stress Range at CAP (Hydrotest), MPa | AA41: Longitudinal Stress Range at CAP (Hydrotest), MPa | AI41: Longitudinal Stress Range at CAP (Hydrotest), MPa
S44: Strain and Stress Ranges | U44: BE-HE | V44: LE-BE | W44: BE-BE | X44: HE-BE | Y44: Input for ECA | AA44: Strain and Stress Ranges | AC44: BE-HE | AD44: LE-BE | AE44: BE-BE | AF44: HE-BE | AG44: Input for ECA | AI44: Strain and Stress Ranges | AK44: BE-HE | AL44: LE-BE | AM44: BE-BE | AN44: HE-BE | AO44: Input for ECA
R45: 12in | S45: Max. Axial Mechanical Tensile Strain OD (Hydrotest) | U45: 0.00179866 | V45: checked | W45: x | Z45: 12in | AA45: Max. Axial Mechanical Tensile Strain OD (Hydrotest) | AC45: 0.00127473 | AD45: checked | AE45: x | AH45: 12in | AI45: Max. Axial Mechanical Tensile Strain OD (Hydrotest) | AK45: 0.00042 | AL45: checked | AM45: x
R46: Sleeper | S46: Max. Axial Total Tensile Strain OD (Hydrotest) | U46: 0.00179866 | V46: checked | W46: x | Z46: Structure | AA46: Max. Axial Total Tensile Strain OD (Hydrotest) | AC46: 0.00127473 | AD46: checked | AE46: x | AH46: Other | AI46: Max. Axial Total Tensile Strain OD (Hydrotest) | AK46: 0.00042 | AL46: checked | AM46: x
S47: Max. Axial Mechanical Tensile Strain Midwall (Hydrotest) | U47: 0.00161753 | V47: checked | W47: x | AA47: Max. Axial Mechanical Tensile Strain Midwall (Hydrotest) | AC47: 0.00114763 | AD47: checked | AE47: x | AI47: Max. Axial Mechanical Tensile Strain Midwall (Hydrotest) | AK47: 0.00039 | AL47: checked | AM47: x
S48: Max. Axial Total Tensile Strain Midwall (Hydrotest) | U48: 0.00161753 | V48: checked | W48: x | AA48: Max. Axial Total Tensile Strain Midwall (Hydrotest) | AC48: 0.00114763 | AD48: checked | AE48: x | AI48: Max. Axial Total Tensile Strain Midwall (Hydrotest) | AK48: 0.00039 | AL48: checked | AM48: x
...

Sheet LE11_BEBE_HO_P2toP1
S1: Strain and Stress Ranges | U1: BE-BE | AA1: Strain and Stress Ranges | AC1: BE-BE | AI1: Strain and Stress Ranges | AK1: BE-BE
R2: 10in | S2: Max. Axial Mechanical Tensile Strain OD (Hydrotest) | U2: 0.00170501 | V2: checked | W2: x | Z2: 10in | AA2: Max. Axial Mechanical Tensile Strain OD (Hydrotest) | AC2: 0.00107281 | AD2: checked | AE2: x | AH2: 10in | AI2: Max. Axial Mechanical Tensile Strain OD (Hydrotest) | AK2: 0.00029 | AL2: checked | AM2: x
R3: Sleeper | S3: Max. Axial Total Tensile Strain OD (Hydrotest) | U3: 0.00170501 | V3: checked | W3: x | Z3: Structure | AA3: Max. Axial Total Tensile Strain OD (Hydrotest) | AC3: 0.00107281 | AD3: checked | AE3: x | AH3: Other | AI3: Max. Axial Total Tensile Strain OD (Hydrotest) | AK3: 0.00029 | AL3: checked | AM3: x
S4: Max. Axial Mechanical Tensile Strain Midwall (Hydrotest) | U4: 0.00151641 | V4: checked | W4: x | AA4: Max. Axial Mechanical Tensile Strain Midwall (Hydrotest) | AC4: 0.000954594 | AD4: checked | AE4: x | AI4: Max. Axial Mechanical Tensile Strain Midwall (Hydrotest) | AK4: 0.00028 | AL4: checked | AM4: x
S5: Max. Axial Total Tensile Strain Midwall (Hydrotest) | U5: 0.00151641 | V5: checked | W5: x | AA5: Max. Axial Total Tensile Strain Midwall (Hydrotest) | AC5: 0.000954594 | AD5: checked | AE5: x | AI5: Max. Axial Total Tensile Strain Midwall (Hydrotest) | AK5: 0.00028 | AL5: checked | AM5: x
S6: Max. Axial Mechanical Tensile Strain OD (Design) | U6: 0.002153191 | V6: checked | W6: x | AA6: Max. Axial Mechanical Tensile Strain OD (Design) | AC6: 0.001129412 | AD6: checked | AE6: x | AI6: Max. Axial Mechanical Tensile Strain OD (Design) | AK6: 0.0009 | AL6: checked | AM6: x
S7: Max. Axial Total Tensile Strain OD (Design) | U7: 0.00319258 | V7: checked | W7: x | AA7: Max. Axial Total Tensile Strain OD (Design) | AC7: 0.00215488 | AD7: checked | AE7: x | AI7: Max. Axial Total Tensile Strain OD (Design) | AK7: 0.0019 | AL7: checked | AM7: x
S8: Max. Axial Mechanical Tensile Strain Midwall (Design) | U8: 0.001900061 | V8: checked | W8: x | AA8: Max. Axial Mechanical Tensile Strain Midwall (Design) | AC8: 0.000994022 | AD8: checked | AE8: x | AI8: Max. Axial Mechanical Tensile Strain Midwall (Design) | AK8: 0.0008 | AL8: checked | AM8: x
S9: Max. Axial Total Tensile Strain Midwall (Design) | U9: 0.0029559 | V9: checked | W9: x | AA9: Max. Axial Total Tensile Strain Midwall (Design) | AC9: 0.00204887 | AD9: checked | AE9: x | AI9: Max. Axial Total Tensile Strain Midwall (Design) | AK9: 0.0018 | AL9: checked | AM9: x
S10: Max. Axial Mechanical Tensile Strain OD (Early Life) | U10: 0.00196 | V10: checked | W10: x | AA10: Max. Axial Mechanical Tensile Strain OD (Early Life) | AC10: 0.00072 | AD10: checked | AE10: x | AI10: Max. Axial Mechanical Tensile Strain OD (Early Life) | AK10: 0.00019 | AL10: checked | AM10: x
S11: Max. Axial Total Tensile Strain OD (Early Life) | U11: 0.00285 | V11: checked | W11: x | AA11: Max. Axial Total Tensile Strain OD (Early Life) | AC11: 0.00123 | AD11: checked | AE11: x | AI11: Max. Axial Total Tensile Strain OD (Early Life) | AK11: 0.001 | AL11: checked | AM11: x
S12: Max. Axial Mechanical Tensile Strain Midwall (Early Life) | U12: 0.00172 | V12: checked | W12: x | AA12: Max. Axial Mechanical Tensile Strain Midwall (Early Life) | AC12: 0.00064 | AD12: checked | AE12: x | AI12: Max. Axial Mechanical Tensile Strain Midwall (Early Life) | AK12: 0.00017 | AL12: checked | AM12: x
S13: Max. Axial Total Tensile Strain Midwall (Early Life) | U13: 0.00261 | V13: checked | W13: x | AA13: Max. Axial Total Tensile Strain Midwall (Early Life) | AC13: 0.00114 | AD13: checked | AE13: x | AI13: Max. Axial Total Tensile Strain Midwall (Early Life) | AK13: 0.00098 | AL13: checked | AM13: x
S14: Max. Axial Mechanical Tensile Strain OD (Mid Life) | U14: 0.00169 | V14: checked | W14: x | AA14: Max. Axial Mechanical Tensile Strain OD (Mid Life) | AC14: 0.00072 | AD14: checked | AE14: x | AI14: Max. Axial Mechanical Tensile Strain OD (Mid Life) | AK14: 0.00019 | AL14: checked | AM14: x
S15: Max. Axial Total Tensile Strain OD (Mid Life) | U15: 0.00253 | V15: checked | AA15: Max. Axial Total Tensile Strain OD (Mid Life) | AC15: 0.00121 | AD15: checked | AI15: Max. Axial Total Tensile Strain OD (Mid Life) | AK15: 0.00101 | AL15: checked
S16: Max. Axial Mechanical Tensile Strain Midwall (Mid Life) | U16: 0.00148 | V16: checked | W16: x | AA16: Max. Axial Mechanical Tensile Strain Midwall (Mid Life) | AC16: 0.00064 | AD16: checked | AE16: x | AI16: Max. Axial Mechanical Tensile Strain Midwall (Mid Life) | AK16: 0.00018 | AL16: checked | AM16: x
S17: Max. Axial Total Tensile Strain Midwall (Mid Life) | U17: 0.00234 | V17: checked | AA17: Max. Axial Total Tensile Strain Midwall (Mid Life) | AC17: 0.00113 | AD17: checked | AI17: Max. Axial Total Tensile Strain Midwall (Mid Life) | AK17: 0.00099 | AL17: checked
S18: Max. Axial Mechanical Tensile Strain OD (Late Life) | U18: 0.00166 | V18: checked | W18: x | AA18: Max. Axial Mechanical Tensile Strain OD (Late Life) | AC18: 0.00072 | AD18: checked | AE18: x | AI18: Max. Axial Mechanical Tensile Strain OD (Late Life) | AK18: 0.0002 | AL18: checked | AM18: x
S19: Max. Axial Total Tensile Strain OD (Late Life) | U19: 0.00254 | V19: checked | W19: x | AA19: Max. Axial Total Tensile Strain OD (Late Life) | AC19: 0.00121 | AD19: checked | AE19: x | AI19: Max. Axial Total Tensile Strain OD (Late Life) | AK19: 0.00102 | AL19: checked | AM19: x
S20: Max. Axial Mechanical Tensile Strain Midwall (Late Life) | U20: 0.00146 | V20: checked | W20: x | AA20: Max. Axial Mechanical Tensile Strain Midwall (Late Life) | AC20: 0.00064 | AD20: checked | AE20: x | AI20: Max. Axial Mechanical Tensile Strain Midwall (Late Life) | AK20: 0.00018 | AL20: checked | AM20: x
S21: Max. Axial Total Tensile Strain Midwall (Late Life) | U21: 0.00235 | V21: checked | W21: x | AA21: Max. Axial Total Tensile Strain Midwall (Late Life) | AC21: 0.00113 | AD21: checked | AE21: x | AI21: Max. Axial Total Tensile Strain Midwall (Late Life) | AK21: 0.001 | AL21: checked | AM21: x
S22: Longitudinal Stress Range at Root, MPa (FCD) | T22: Early Life (1 to 15 yr) | AA22: Longitudinal Stress Range at Root, MPa (FCD) | AB22: Early Life (1 to 15 yr) | AI22: Longitudinal Stress Range at Root, MPa (FCD) | AJ22: Early Life (1 to 15 yr)
T24: Late Life (16 to 25 yr) | AB24: Late Life (16 to 25 yr) | AJ24: Late Life (16 to 25 yr)
S25: Longitudinal Stress Range at Root, MPa (PCD) | T25: Early Life (1 to 15 yr) | AA25: Longitudinal Stress Range at Root, MPa (PCD) | AB25: Early Life (1 to 15 yr) | AI25: Longitudinal Stress Range at Root, MPa (PCD) | AJ25: Early Life (1 to 15 yr)
T27: Late Life (16 to 25 yr) | AB27: Late Life (16 to 25 yr) | AJ27: Late Life (16 to 25 yr)
S28: Longitudinal Stress Range at Root, MPa (Between Hot Oiling) | T28: Early Life (1 to 15 yr) | AA28: Longitudinal Stress Range at Root, MPa (Between Hot Oiling) | AB28: Early Life (1 to 15 yr) | AI28: Longitudinal Stress Range at Root, MPa (Between Hot Oiling) | AJ28: Early Life (1 to 15 yr)
T30: Late Life (16 to 25 yr) | AB30: Late Life (16 to 25 yr) | AJ30: Late Life (16 to 25 yr)
S31: Longitudinal Stress Range at Root (Hydrotest), MPa | AA31: Longitudinal Stress Range at Root (Hydrotest), MPa | AI31: Longitudinal Stress Range at Root (Hydrotest), MPa
S32: Longitudinal Stress Range at Cap, MPa (FCD) | T32: Early Life (1 to 15 yr) | AA32: Longitudinal Stress Range at Cap, MPa (FCD) | AB32: Early Life (1 to 15 yr) | AI32: Longitudinal Stress Range at Cap, MPa (FCD) | AJ32: Early Life (1 to 15 yr)
T34: Late Life (16 to 25 yr) | AB34: Late Life (16 to 25 yr) | AJ34: Late Life (16 to 25 yr)
S35: Longitudinal Stress Range at Cap, MPa (PCD) | T35: Early Life (1 to 15 yr) | AA35: Longitudinal Stress Range at Cap, MPa (PCD) | AB35: Early Life (1 to 15 yr) | AI35: Longitudinal Stress Range at Cap, MPa (PCD) | AJ35: Early Life (1 to 15 yr)
T37: Late Life (16 to 25 yr) | AB37: Late Life (16 to 25 yr) | AJ37: Late Life (16 to 25 yr)
S38: Longitudinal Stress Range at Root, MPa (Between Hot Oiling) | T38: Early Life (1 to 15 yr) | AA38: Longitudinal Stress Range at Root, MPa (Between Hot Oiling) | AB38: Early Life (1 to 15 yr) | AI38: Longitudinal Stress Range at Root, MPa (Between Hot Oiling) | AJ38: Early Life (1 to 15 yr)
T40: Late Life (16 to 25 yr) | AB40: Late Life (16 to 25 yr) | AJ40: Late Life (16 to 25 yr)
S41: Longitudinal Stress Range at CAP (Hydrotest), MPa | AA41: Longitudinal Stress Range at CAP (Hydrotest), MPa | AI41: Longitudinal Stress Range at CAP (Hydrotest), MPa
S44: Strain and Stress Ranges | U44: BE-HE | V44: LE-BE | W44: BE-BE | X44: HE-BE | Y44: Input for ECA | AA44: Strain and Stress Ranges | AC44: BE-HE | AD44: LE-BE | AE44: BE-BE | AF44: HE-BE | AG44: Input for ECA | AI44: Strain and Stress Ranges | AK44: BE-HE | AL44: LE-BE | AM44: BE-BE | AN44: HE-BE | AO44: Input for ECA
