Workbook

Sheet BE-HE_P1toP2
P1: Strain and Stress Ranges | R1: BE-HE | X1: Strain and Stress Ranges | Z1: BE-HE | AF1: Strain and Stress Ranges | AH1: BE-HE
O2: 10in | P2: Max. Axial Mechanical Tensile Strain OD (Hydrotest) | W2: 10in | X2: Max. Axial Mechanical Tensile Strain OD (Hydrotest) | AE2: 10in | AF2: Max. Axial Mechanical Tensile Strain OD (Hydrotest)
O3: Sleeper | P3: Max. Axial Total Tensile Strain OD (Hydrotest) | W3: Structure | X3: Max. Axial Total Tensile Strain OD (Hydrotest) | AE3: Other | AF3: Max. Axial Total Tensile Strain OD (Hydrotest)
P4: Max. Axial Mechanical Tensile Strain ID (Hydrotest) | X4: Max. Axial Mechanical Tensile Strain ID (Hydrotest) | AF4: Max. Axial Mechanical Tensile Strain ID (Hydrotest)
P5: Max. Axial Total Tensile Strain ID (Hydrotest) | X5: Max. Axial Total Tensile Strain ID (Hydrotest) | AF5: Max. Axial Total Tensile Strain ID (Hydrotest)
P6: Max. Axial Mechanical Tensile Strain OD (Design) | X6: Max. Axial Mechanical Tensile Strain OD (Design) | AF6: Max. Axial Mechanical Tensile Strain OD (Design)
P7: Max. Axial Total Tensile Strain OD (Design) | X7: Max. Axial Total Tensile Strain OD (Design) | AF7: Max. Axial Total Tensile Strain OD (Design)
P8: Max. Axial Mechanical Tensile Strain ID (Design) | X8: Max. Axial Mechanical Tensile Strain ID (Design) | AF8: Max. Axial Mechanical Tensile Strain ID (Design)
P9: Max. Axial Total Tensile Strain ID (Design) | X9: Max. Axial Total Tensile Strain ID (Design) | AF9: Max. Axial Total Tensile Strain ID (Design)
P10: Max. Axial Mechanical Tensile Strain OD (Early Life) | X10: Max. Axial Mechanical Tensile Strain OD (Early Life) | AF10: Max. Axial Mechanical Tensile Strain OD (Early Life)
P11: Max. Axial Total Tensile Strain OD (Early Life) | X11: Max. Axial Total Tensile Strain OD (Early Life) | AF11: Max. Axial Total Tensile Strain OD (Early Life)
P12: Max. Axial Mechanical Tensile Strain ID (Early Life) | X12: Max. Axial Mechanical Tensile Strain ID (Early Life) | AF12: Max. Axial Mechanical Tensile Strain ID (Early Life)
P13: Max. Axial Total Tensile Strain ID (Early Life) | X13: Max. Axial Total Tensile Strain ID (Early Life) | AF13: Max. Axial Total Tensile Strain ID (Early Life)
P14: Max. Axial Mechanical Tensile Strain OD (Late Life) | X14: Max. Axial Mechanical Tensile Strain OD (Late Life) | AF14: Max. Axial Mechanical Tensile Strain OD (Late Life)
P15: Max. Axial Total Tensile Strain OD (Late Life) | X15: Max. Axial Total Tensile Strain OD (Late Life) | AF15: Max. Axial Total Tensile Strain OD (Late Life)
... P17: Max. Axial Total Tensile Strain ID (Late Life) | X17: Max. Axial Total Tensile Strain ID (Late Life) | AF17: Max. Axial Total Tensile Strain ID (Late Life)
P18: Longitudinal Stress Range at MidWall, MPa (FCD) | Q18: Early Life (1 to 9 yr) | R18: 272.5185 | S18: =R18*(33/30) -> 299.77035 | T18: checked | U18: x | X18: Longitudinal Stress Range at MidWall, MPa (FCD) | Y18: Early Life (1 to 15 yr) | Z18: 81.690166 | AA18: =Z18*(33/30) -> 89.859183 | AB18: checked | AC18: x | AF18: Longitudinal Stress Range at MidWall, MPa (FCD) | AG18: Early Life (1 to 9 yr) | AH18: 52.435752 | AI18: =AH18*(33/30) -> 57.679327 | AJ18: checked | AK18: x
Q19: Mid Life (10 to 15 yr) | R19: 257.43662 | S19: =R19*(33/30) -> 283.18028 | Y19: Mid Life (10 to 15 yr) | Z19: 80.4867 | AA19: =Z19*(33/30) -> 88.53537 | AG19: Mid Life (10 to 15 yr) | AH19: 52.065058 | AI19: =AH19*(33/30) -> 57.271564
Q20: Late Life (16 to 25 yr) | R20: 257.75939 | S20: =R20*(33/30) -> 283.53533 | T20: checked | U20: x | Y20: Late Life (16 to 25 yr) | Z20: 80.939694 | AA20: =Z20*(33/30) -> 89.033663 | AB20: checked | AC20: x | AG20: Late Life (16 to 25 yr) | AH20: 52.011187 | AI20: =AH20*(33/30) -> 57.212306 | AJ20: checked | AK20: x
P21: Longitudinal Stress Range at MidWall, MPa (PCD) | Q21: Early Life (1 to 9 yr) | R21: 95.723004 | S21: =R21*(33/30) -> 105.2953 | T21: checked | U21: x | X21: Longitudinal Stress Range at MidWall, MPa (PCD) | Y21: Early Life (1 to 9 yr) | Z21: 46.638424 | AA21: =Z21*(33/30) -> 51.302266 | AB21: checked | AC21: x | AF21: Longitudinal Stress Range at MidWall, MPa (PCD) | AG21: Early Life (1 to 9 yr) | AH21: 25.641148 | AI21: =AH21*(33/30) -> 28.205263 | AJ21: checked | AK21: x
Q22: Mid Life (10 to 15 yr) | R22: 70.898492 | S22: =R22*(33/30) -> 77.988341 | Y22: Mid Life (10 to 15 yr) | Z22: 34.015404 | AA22: =Z22*(33/30) -> 37.416944 | AG22: Mid Life (10 to 15 yr) | AH22: 19.599053 | AI22: =AH22*(33/30) -> 21.558958
Q23: Late Life (16 to 25 yr) | R23: 71.097768 | S23: =R23*(33/30) -> 78.207545 | T23: checked | U23: x | Y23: Late Life (16 to 25 yr) | Z23: 36.35367 | AA23: =Z23*(33/30) -> 39.989037 | AB23: checked | AC23: x | AG23: Late Life (16 to 25 yr) | AH23: 22.550618 | AI23: =AH23*(33/30) -> 24.80568 | AJ23: checked | AK23: x
P24: Longitudinal Stress Range at MidWall, MPa (Between Hot Oiling) | Q24: Early Life (1 to 9 yr) | R24: 262.9362 | S24: =R24*(33/30) -> 289.22982 | T24: checked | U24: x | X24: Longitudinal Stress Range at MidWall, MPa (Between Hot Oiling) | Y24: Early Life (1 to 9 yr) | Z24: 50.283734 | AA24: =Z24*(33/30) -> 55.312107 | AB24: checked | AC24: x | AF24: Longitudinal Stress Range at MidWall, MPa (Between Hot Oiling) | AG24: Early Life (1 to 9 yr) | AH24: 34.799299 | AI24: =AH24*(33/30) -> 38.279229 | AJ24: checked | AK24: x
Q25: Mid Life (10 to 15 yr) | R25: 184.48921 | S25: =R25*(33/30) -> 202.93813 | Y25: Mid Life (10 to 15 yr) | Z25: 50.820504 | AA25: =Z25*(33/30) -> 55.902554 | AG25: Mid Life (10 to 15 yr) | AH25: 29.879916 | AI25: =AH25*(33/30) -> 32.867908 | AJ25: checked
Q26: Late Life (16 to 25 yr) | R26: 184.47419 | S26: =R26*(33/30) -> 202.9216 | T26: checked | U26: x | Y26: Late Life (16 to 25 yr) | Z26: 52.672068 | AA26: =Z26*(33/30) -> 57.939275 | AB26: checked | AC26: x | AG26: Late Life (16 to 25 yr) | AH26: 31.69288 | AI26: =AH26*(33/30) -> 34.862167 | AJ26: checked | AK26: x
P27: Longitudinal Stress Range at Midwall (Hydrotest), MPa | R27: 257.69429 | S27: =R27*(33/33) -> 257.69429 | T27: checked | U27: x | X27: Longitudinal Stress Range at Midwall (Hydrotest), MPa | Z27: 163.51738 | AA27: =Z27*(33/33) -> 163.51738 | AB27: checked | AC27: x | AF27: Longitudinal Stress Range at Midwall (Hydrotest), MPa | AH27: 142.3 | AI27: =AH27 -> 142.3 | AJ27: checked | AK27: x
P28: Longitudinal Stress Range at Cap, MPa (FCD) | Q28: Early Life (1 to 9 yr) | R28: 309.11214 | S28: =R28*(33/30) -> 340.02336 | T28: checked | U28: x | X28: Longitudinal Stress Range at Cap, MPa (FCD) | Y28: Early Life (1 to 9 yr) | Z28: 86.45202 | AA28: =Z28*(33/30) -> 95.097222 | AB28: checked | AC28: x | AF28: Longitudinal Stress Range at Cap, MPa (FCD) | AG28: Early Life (1 to 9 yr) | AH28: 52.587956 | AI28: =AH28*(33/30) -> 57.846752 | AJ28: checked | AK28: x
Q29: Mid Life (10 to 15 yr) | R29: 289.98902 | S29: =R29*(33/30) -> 318.98793 | Y29: Mid Life (10 to 15 yr) | Z29: 85.794078 | AA29: =Z29*(33/30) -> 94.373486 | AG29: Mid Life (10 to 15 yr) | AH29: 52.198681 | AI29: =AH29*(33/30) -> 57.418549
Q30: Late Life (16 to 25 yr) | R30: 290.70482 | S30: =R30*(33/30) -> 319.7753 | T30: checked | U30: x | Y30: Late Life (16 to 25 yr) | Z30: 86.289618 | AA30: =Z30*(33/30) -> 94.91858 | AB30: checked | AC30: x | AG30: Late Life (16 to 25 yr) | AH30: 52.14745 | AI30: =AH30*(33/30) -> 57.362195 | AJ30: checked | AK30: x
P31: Longitudinal Stress Range at Cap, MPa (PCD) | Q31: Early Life (1 to 9 yr) | R31: 108.30923 | S31: =R31*(33/30) -> 119.14016 | T31: checked | U31: x | X31: Longitudinal Stress Range at Cap, MPa (PCD) | Y31: Early Life (1 to 9 yr) | Z31: 43.454136 | AA31: =Z31*(33/30) -> 47.79955 | AB31: checked | AC31: x | AF31: Longitudinal Stress Range at Cap, MPa (PCD) | AG31: Early Life (1 to 9 yr) | AH31: 26.02629 | AI31: =AH31*(33/30) -> 28.628919 | AJ31: checked | AK31: x
Q32: Mid Life (10 to 15 yr) | R32: 79.988408 | S32: =R32*(33/30) -> 87.987249 | Y32: Mid Life (10 to 15 yr) | Z32: 36.454376 | AA32: =Z32*(33/30) -> 40.099814 | AG32: Mid Life (10 to 15 yr) | AH32: 19.991138 | AI32: =AH32*(33/30) -> 21.990252
Q33: Late Life (16 to 25 yr) | R33: 80.254896 | S33: =R33*(33/30) -> 88.280386 | T33: checked | U33: x | Y33: Late Life (16 to 25 yr) | Z33: 40.341032 | AA33: =Z33*(33/30) -> 44.375135 | AB33: checked | AC33: x | AG33: Late Life (16 to 25 yr) | AH33: 23.142534 | AI33: =AH33*(33/30) -> 25.456787 | AJ33: checked | AK33: x
P34: Longitudinal Stress Range at Cap, MPa (Between Hot Oiling) | Q34: Early Life (1 to 9 yr) | R34: 294.21514 | S34: =R34*(33/30) -> 323.63665 | T34: checked | U34: x | X34: Longitudinal Stress Range at Cap, MPa (Between Hot Oiling) | Y34: Early Life (1 to 9 yr) | Z34: 59.24906 | AA34: =Z34*(33/30) -> 65.173966 | AB34: checked | AC34: x | AF34: Longitudinal Stress Range at Cap, MPa (Between Hot Oiling) | AG34: Early Life (1 to 9 yr) | AH34: 34.769156 | AI34: =AH34*(33/30) -> 38.246072 | AJ34: checked | AK34: x
Q35: Mid Life (10 to 15 yr) | R35: 205.84825 | S35: =R35*(33/30) -> 226.43308 | Y35: Mid Life (10 to 15 yr) | Z35: 55.394804 | AA35: =Z35*(33/30) -> 60.934284 | AG35: Mid Life (10 to 15 yr) | AH35: 30.125788 | AI35: =AH35*(33/30) -> 33.138366
Q36: Late Life (16 to 25 yr) | R36: 205.86737 | S36: =R36*(33/30) -> 226.45411 | T36: checked | U36: x | Y36: Late Life (16 to 25 yr) | Z36: 57.28958 | AA36: =Z36*(33/30) -> 63.018538 | AB36: checked | AC36: x | AG36: Late Life (16 to 25 yr) | AH36: 31.94841 | AI36: =AH36*(33/30) -> 35.14325 | AJ36: checked | AK36: x
P37: Longitudinal Stress Range at CAP (Hydrotest), MPa | R37: 277.22238 | S37: =R37*(33/33) -> 277.22238 | T37: checked | U37: x | X37: Longitudinal Stress Range at CAP (Hydrotest), MPa | Z37: 172.1276 | AA37: =Z37*(33/33) -> 172.1276 | AB37: checked | AC37: x | AF37: Longitudinal Stress Range at CAP (Hydrotest), MPa | AH37: 146.1 | AI37: =AH37*(33/33) -> 146.1 | AJ37: checked | AK37: x
P40: Strain and Stress Ranges | R40: BE-HE | T40: BE-BE | U40: HE-BE | V40: Input for ECA | X40: Strain and Stress Ranges | Z40: BE-HE | AB40: BE-BE | AC40: HE-BE | AD40: Input for ECA | AF40: Strain and Stress Ranges | AH40: BE-HE | AJ40: BE-BE | AK40: HE-BE | AL40: Input for ECA
O41: 12in | P41: Max. Axial Mechanical Tensile Strain OD (Hydrotest) | W41: 12in | X41: Max. Axial Mechanical Tensile Strain OD (Hydrotest) | AE41: 12in | AF41: Max. Axial Mechanical Tensile Strain OD (Hydrotest)
O42: Sleeper | P42: Max. Axial Total Tensile Strain OD (Hydrotest) | W42: Structure | X42: Max. Axial Total Tensile Strain OD (Hydrotest) | AE42: Other | AF42: Max. Axial Total Tensile Strain OD (Hydrotest)
P43: Max. Axial Mechanical Tensile Strain ID (Hydrotest) | X43: Max. Axial Mechanical Tensile Strain ID (Hydrotest) | AF43: Max. Axial Mechanical Tensile Strain ID (Hydrotest)
...

Sheet BE-HE_P2toP1
P1: Strain and Stress Ranges | R1: BE-HE | X1: Strain and Stress Ranges | Z1: BE-HE | AF1: Strain and Stress Ranges | AH1: BE-HE
O2: 10in | P2: Max. Axial Mechanical Tensile Strain OD (Hydrotest) | W2: 10in | X2: Max. Axial Mechanical Tensile Strain OD (Hydrotest) | AE2: 10in | AF2: Max. Axial Mechanical Tensile Strain OD (Hydrotest)
O3: Sleeper | P3: Max. Axial Total Tensile Strain OD (Hydrotest) | W3: Structure | X3: Max. Axial Total Tensile Strain OD (Hydrotest) | AE3: Other | AF3: Max. Axial Total Tensile Strain OD (Hydrotest)
P4: Max. Axial Mechanical Tensile Strain ID (Hydrotest) | X4: Max. Axial Mechanical Tensile Strain ID (Hydrotest) | AF4: Max. Axial Mechanical Tensile Strain ID (Hydrotest)
P5: Max. Axial Total Tensile Strain ID (Hydrotest) | X5: Max. Axial Total Tensile Strain ID (Hydrotest) | AF5: Max. Axial Total Tensile Strain ID (Hydrotest)
P6: Max. Axial Mechanical Tensile Strain OD (Design) | X6: Max. Axial Mechanical Tensile Strain OD (Design) | AF6: Max. Axial Mechanical Tensile Strain OD (Design)
P7: Max. Axial Total Tensile Strain OD (Design) | X7: Max. Axial Total Tensile Strain OD (Design) | AF7: Max. Axial Total Tensile Strain OD (Design)
P8: Max. Axial Mechanical Tensile Strain ID (Design) | X8: Max. Axial Mechanical Tensile Strain ID (Design) | AF8: Max. Axial Mechanical Tensile Strain ID (Design)
P9: Max. Axial Total Tensile Strain ID (Design) | X9: Max. Axial Total Tensile Strain ID (Design) | AF9: Max. Axial Total Tensile Strain ID (Design)
P10: Max. Axial Mechanical Tensile Strain OD (Early Life) | X10: Max. Axial Mechanical Tensile Strain OD (Early Life) | AF10: Max. Axial Mechanical Tensile Strain OD (Early Life)
P11: Max. Axial Total Tensile Strain OD (Early Life) | X11: Max. Axial Total Tensile Strain OD (Early Life) | AF11: Max. Axial Total Tensile Strain OD (Early Life)
P12: Max. Axial Mechanical Tensile Strain ID (Early Life) | X12: Max. Axial Mechanical Tensile Strain ID (Early Life) | AF12: Max. Axial Mechanical Tensile Strain ID (Early Life)
P13: Max. Axial Total Tensile Strain ID (Early Life) | X13: Max. Axial Total Tensile Strain ID (Early Life) | AF13: Max. Axial Total Tensile Strain ID (Early Life)
P14: Max. Axial Mechanical Tensile Strain OD (Late Life) | X14: Max. Axial Mechanical Tensile Strain OD (Late Life) | AF14: Max. Axial Mechanical Tensile Strain OD (Late Life)
P15: Max. Axial Total Tensile Strain OD (Late Life) | X15: Max. Axial Total Tensile Strain OD (Late Life) | AF15: Max. Axial Total Tensile Strain OD (Late Life)
... P17: Max. Axial Total Tensile Strain ID (Late Life) | X17: Max. Axial Total Tensile Strain ID (Late Life) | AF17: Max. Axial Total Tensile Strain ID (Late Life)
P18: Longitudinal Stress Range at MidWall, MPa (FCD) | Q18: Early Life (1 to 9 yr) | S18: =R18*(33/30) -> 0 | T18: checked | U18: x | X18: Longitudinal Stress Range at MidWall, MPa (FCD) | Y18: Early Life (1 to 15 yr) | AA18: =Z18*(33/30) -> 0 | AB18: checked | AC18: x | AF18: Longitudinal Stress Range at MidWall, MPa (FCD) | AG18: Early Life (1 to 9 yr) | AI18: =AH18*(33/30) -> 0 | AJ18: checked | AK18: x
Q19: Mid Life (10 to 15 yr) | S19: =R19*(33/30) -> 0 | Y19: Mid Life (10 to 15 yr) | AA19: =Z19*(33/30) -> 0 | AG19: Mid Life (10 to 15 yr) | AI19: =AH19*(33/30) -> 0
Q20: Late Life (16 to 25 yr) | S20: =R20*(33/30) -> 0 | T20: checked | U20: x | Y20: Late Life (16 to 25 yr) | AA20: =Z20*(33/30) -> 0 | AB20: checked | AC20: x | AG20: Late Life (16 to 25 yr) | AI20: =AH20*(33/30) -> 0 | AJ20: checked | AK20: x
P21: Longitudinal Stress Range at MidWall, MPa (PCD) | Q21: Early Life (1 to 9 yr) | S21: =R21*(33/30) -> 0 | T21: checked | U21: x | X21: Longitudinal Stress Range at MidWall, MPa (PCD) | Y21: Early Life (1 to 9 yr) | AA21: =Z21*(33/30) -> 0 | AB21: checked | AC21: x | AF21: Longitudinal Stress Range at MidWall, MPa (PCD) | AG21: Early Life (1 to 9 yr) | AI21: =AH21*(33/30) -> 0 | AJ21: checked | AK21: x
Q22: Mid Life (10 to 15 yr) | S22: =R22*(33/30) -> 0 | Y22: Mid Life (10 to 15 yr) | AA22: =Z22*(33/30) -> 0 | AG22: Mid Life (10 to 15 yr) | AI22: =AH22*(33/30) -> 0
Q23: Late Life (16 to 25 yr) | S23: =R23*(33/30) -> 0 | T23: checked | U23: x | Y23: Late Life (16 to 25 yr) | AA23: =Z23*(33/30) -> 0 | AB23: checked | AC23: x | AG23: Late Life (16 to 25 yr) | AI23: =AH23*(33/30) -> 0 | AJ23: checked | AK23: x
P24: Longitudinal Stress Range at MidWall, MPa (Between Hot Oiling) | Q24: Early Life (1 to 9 yr) | S24: =R24*(33/30) -> 0 | T24: checked | U24: x | X24: Longitudinal Stress Range at MidWall, MPa (Between Hot Oiling) | Y24: Early Life (1 to 9 yr) | AA24: =Z24*(33/30) -> 0 | AB24: checked | AC24: x | AF24: Longitudinal Stress Range at MidWall, MPa (Between Hot Oiling) | AG24: Early Life (1 to 9 yr) | AI24: =AH24*(33/30) -> 0 | AJ24: checked | AK24: x
Q25: Mid Life (10 to 15 yr) | S25: =R25*(33/30) -> 0 | Y25: Mid Life (10 to 15 yr) | AA25: =Z25*(33/30) -> 0 | AG25: Mid Life (10 to 15 yr) | AI25: =AH25*(33/30) -> 0 | AJ25: checked
Q26: Late Life (16 to 25 yr) | S26: =R26*(33/30) -> 0 | T26: checked | U26: x | Y26: Late Life (16 to 25 yr) | AA26: =Z26*(33/30) -> 0 | AB26: checked | AC26: x | AG26: Late Life (16 to 25 yr) | AI26: =AH26*(33/30) -> 0 | AJ26: checked | AK26: x
P27: Longitudinal Stress Range at Midwall (Hydrotest), MPa | R27: 257.69429 | S27: =R27*(33/33) -> 257.69429 | T27: checked | U27: x | X27: Longitudinal Stress Range at Midwall (Hydrotest), MPa | Z27: 163.51738 | AA27: =Z27*(33/33) -> 163.51738 | AB27: checked | AC27: x | AF27: Longitudinal Stress Range at Midwall (Hydrotest), MPa | AH27: 142.3 | AI27: =AH27 -> 142.3 | AJ27: checked | AK27: x
P28: Longitudinal Stress Range at Cap, MPa (FCD) | Q28: Early Life (1 to 9 yr) | S28: =R28*(33/30) -> 0 | T28: checked | U28: x | X28: Longitudinal Stress Range at Cap, MPa (FCD) | Y28: Early Life (1 to 9 yr) | AA28: =Z28*(33/30) -> 0 | AB28: checked | AC28: x | AF28: Longitudinal Stress Range at Cap, MPa (FCD) | AG28: Early Life (1 to 9 yr) | AI28: =AH28*(33/30) -> 0 | AJ28: checked | AK28: x
Q29: Mid Life (10 to 15 yr) | S29: =R29*(33/30) -> 0 | Y29: Mid Life (10 to 15 yr) | AA29: =Z29*(33/30) -> 0 | AG29: Mid Life (10 to 15 yr) | AI29: =AH29*(33/30) -> 0
Q30: Late Life (16 to 25 yr) | S30: =R30*(33/30) -> 0 | T30: checked | U30: x | Y30: Late Life (16 to 25 yr) | AA30: =Z30*(33/30) -> 0 | AB30: checked | AC30: x | AG30: Late Life (16 to 25 yr) | AI30: =AH30*(33/30) -> 0 | AJ30: checked | AK30: x
P31: Longitudinal Stress Range at Cap, MPa (PCD) | Q31: Early Life (1 to 9 yr) | S31: =R31*(33/30) -> 0 | T31: checked | U31: x | X31: Longitudinal Stress Range at Cap, MPa (PCD) | Y31: Early Life (1 to 9 yr) | AA31: =Z31*(33/30) -> 0 | AB31: checked | AC31: x | AF31: Longitudinal Stress Range at Cap, MPa (PCD) | AG31: Early Life (1 to 9 yr) | AI31: =AH31*(33/30) -> 0 | AJ31: checked | AK31: x
Q32: Mid Life (10 to 15 yr) | S32: =R32*(33/30) -> 0 | Y32: Mid Life (10 to 15 yr) | AA32: =Z32*(33/30) -> 0 | AG32: Mid Life (10 to 15 yr) | AI32: =AH32*(33/30) -> 0
Q33: Late Life (16 to 25 yr) | S33: =R33*(33/30) -> 0 | T33: checked | U33: x | Y33: Late Life (16 to 25 yr) | AA33: =Z33*(33/30) -> 0 | AB33: checked | AC33: x | AG33: Late Life (16 to 25 yr) | AI33: =AH33*(33/30) -> 0 | AJ33: checked | AK33: x
P34: Longitudinal Stress Range at Cap, MPa (Between Hot Oiling) | Q34: Early Life (1 to 9 yr) | S34: =R34*(33/30) -> 0 | T34: checked | U34: x | X34: Longitudinal Stress Range at Cap, MPa (Between Hot Oiling) | Y34: Early Life (1 to 9 yr) | AA34: =Z34*(33/30) -> 0 | AB34: checked | AC34: x | AF34: Longitudinal Stress Range at Cap, MPa (Between Hot Oiling) | AG34: Early Life (1 to 9 yr) | AI34: =AH34*(33/30) -> 0 | AJ34: checked | AK34: x
Q35: Mid Life (10 to 15 yr) | S35: =R35*(33/30) -> 0 | Y35: Mid Life (10 to 15 yr) | AA35: =Z35*(33/30) -> 0 | AG35: Mid Life (10 to 15 yr) | AI35: =AH35*(33/30) -> 0
Q36: Late Life (16 to 25 yr) | S36: =R36*(33/30) -> 0 | T36: checked | U36: x | Y36: Late Life (16 to 25 yr) | AA36: =Z36*(33/30) -> 0 | AB36: checked | AC36: x | AG36: Late Life (16 to 25 yr) | AI36: =AH36*(33/30) -> 0 | AJ36: checked | AK36: x
P37: Longitudinal Stress Range at CAP (Hydrotest), MPa | R37: 277.22238 | S37: =R37*(33/33) -> 277.22238 | T37: checked | U37: x | X37: Longitudinal Stress Range at CAP (Hydrotest), MPa | Z37: 172.1276 | AA37: =Z37*(33/33) -> 172.1276 | AB37: checked | AC37: x | AF37: Longitudinal Stress Range at CAP (Hydrotest), MPa | AH37: 146.1 | AI37: =AH37*(33/33) -> 146.1 | AJ37: checked | AK37: x
P40: Strain and Stress Ranges | R40: BE-HE | T40: BE-BE | U40: HE-BE | V40: Input for ECA | X40: Strain and Stress Ranges | Z40: BE-HE | AB40: BE-BE | AC40: HE-BE | AD40: Input for ECA | AF40: Strain and Stress Ranges | AH40: BE-HE | AJ40: BE-BE | AK40: HE-BE | AL40: Input for ECA
O41: 12in | P41: Max. Axial Mechanical Tensile Strain OD (Hydrotest) | W41: 12in | X41: Max. Axial Mechanical Tensile Strain OD (Hydrotest) | AE41: 12in | AF41: Max. Axial Mechanical Tensile Strain OD (Hydrotest)
O42: Sleeper | P42: Max. Axial Total Tensile Strain OD (Hydrotest) | W42: Structure | X42: Max. Axial Total Tensile Strain OD (Hydrotest) | AE42: Other | AF42: Max. Axial Total Tensile Strain OD (Hydrotest)
P43: Max. Axial Mechanical Tensile Strain ID (Hydrotest) | X43: Max. Axial Mechanical Tensile Strain ID (Hydrotest) | AF43: Max. Axial Mechanical Tensile Strain ID (Hydrotest)
...

Sheet BE-BE_P1toP2
P1: Strain and Stress Ranges | R1: BE-BE | X1: Strain and Stress Ranges | Z1: BE-BE | AF1: Strain and Stress Ranges | AH1: BE-BE
O2: 10in | P2: Max. Axial Mechanical Tensile Strain OD (Hydrotest) | W2: 10in | X2: Max. Axial Mechanical Tensile Strain OD (Hydrotest) | AE2: 10in | AF2: Max. Axial Mechanical Tensile Strain OD (Hydrotest)
O3: Sleeper | P3: Max. Axial Total Tensile Strain OD (Hydrotest) | W3: Structure | X3: Max. Axial Total Tensile Strain OD (Hydrotest) | AE3: Other | AF3: Max. Axial Total Tensile Strain OD (Hydrotest)
P4: Max. Axial Mechanical Tensile Strain ID (Hydrotest) | X4: Max. Axial Mechanical Tensile Strain ID (Hydrotest) | AF4: Max. Axial Mechanical Tensile Strain ID (Hydrotest)
P5: Max. Axial Total Tensile Strain ID (Hydrotest) | X5: Max. Axial Total Tensile Strain ID (Hydrotest) | AF5: Max. Axial Total Tensile Strain ID (Hydrotest)
P6: Max. Axial Mechanical Tensile Strain OD (Design) | X6: Max. Axial Mechanical Tensile Strain OD (Design) | AF6: Max. Axial Mechanical Tensile Strain OD (Design)
P7: Max. Axial Total Tensile Strain OD (Design) | X7: Max. Axial Total Tensile Strain OD (Design) | AF7: Max. Axial Total Tensile Strain OD (Design)
P8: Max. Axial Mechanical Tensile Strain ID (Design) | X8: Max. Axial Mechanical Tensile Strain ID (Design) | AF8: Max. Axial Mechanical Tensile Strain ID (Design)
P9: Max. Axial Total Tensile Strain ID (Design) | X9: Max. Axial Total Tensile Strain ID (Design) | AF9: Max. Axial Total Tensile Strain ID (Design)
P10: Max. Axial Mechanical Tensile Strain OD (Early Life) | X10: Max. Axial Mechanical Tensile Strain OD (Early Life) | AF10: Max. Axial Mechanical Tensile Strain OD (Early Life)
P11: Max. Axial Total Tensile Strain OD (Early Life) | X11: Max. Axial Total Tensile Strain OD (Early Life) | AF11: Max. Axial Total Tensile Strain OD (Early Life)
P12: Max. Axial Mechanical Tensile Strain ID (Early Life) | X12: Max. Axial Mechanical Tensile Strain ID (Early Life) | AF12: Max. Axial Mechanical Tensile Strain ID (Early Life)
P13: Max. Axial Total Tensile Strain ID (Early Life) | X13: Max. Axial Total Tensile Strain ID (Early Life) | AF13: Max. Axial Total Tensile Strain ID (Early Life)
P14: Max. Axial Mechanical Tensile Strain OD (Late Life) | X14: Max. Axial Mechanical Tensile Strain OD (Late Life) | AF14: Max. Axial Mechanical Tensile Strain OD (Late Life)
P15: Max. Axial Total Tensile Strain OD (Late Life) | X15: Max. Axial Total Tensile Strain OD (Late Life) | AF15: Max. Axial Total Tensile Strain OD (Late Life)
... P17: Max. Axial Total Tensile Strain ID (Late Life) | X17: Max. Axial Total Tensile Strain ID (Late Life) | AF17: Max. Axial Total Tensile Strain ID (Late Life)
P18: Longitudinal Stress Range at MidWall, MPa (FCD) | Q18: Early Life (1 to 9 yr) | R18: 237.92414 | S18: =R18*(33/30) -> 261.71655 | T18: checked | U18: x | X18: Longitudinal Stress Range at MidWall, MPa (FCD) | Y18: Early Life (1 to 9 yr) | Z18: 80.831584 | AA18: =Z18*(33/30) -> 88.914742 | AB18: checked | AC18: x | AF18: Longitudinal Stress Range at MidWall, MPa (FCD) | AG18: Early Life (1 to 9 yr) | AH18: 52.857608 | AI18: =AH18*(33/30) -> 58.143369 | AJ18: checked | AK18: x
Q19: Mid Life (10 to 15 yr) | R19: 228.96671 | S19: =R19*(33/30) -> 251.86338 | Y19: Mid Life (10 to 15 yr) | Z19: 82.687432 | AA19: =Z19*(33/30) -> 90.956175 | AG19: Mid Life (10 to 15 yr) | AH19: 52.49224 | AI19: =AH19*(33/30) -> 57.741464
Q20: Late Life (16 to 25 yr) | R20: 231.05079 | S20: =R20*(33/30) -> 254.15587 | T20: checked | U20: x | Y20: Late Life (16 to 25 yr) | Z20: 83.623908 | AA20: =Z20*(33/30) -> 91.986299 | AB20: checked | AC20: x | AG20: Late Life (16 to 25 yr) | AH20: 52.481115 | AI20: =AH20*(33/30) -> 57.729227 | AJ20: checked | AK20: x
P21: Longitudinal Stress Range at MidWall, MPa (PCD) | Q21: Early Life (1 to 9 yr) | R21: 88.525586 | S21: =R21*(33/30) -> 97.378145 | T21: checked | U21: x | X21: Longitudinal Stress Range at MidWall, MPa (PCD) | Y21: Early Life (1 to 9 yr) | Z21: 46.638424 | AA21: =Z21*(33/30) -> 51.302266 | AB21: checked | AC21: x | AF21: Longitudinal Stress Range at MidWall, MPa (PCD) | AG21: Early Life (1 to 9 yr) | AH21: 25.970224 | AI21: =AH21*(33/30) -> 28.567246 | AJ21: checked | AK21: x
Q22: Mid Life (10 to 15 yr) | R22: 64.188312 | S22: =R22*(33/30) -> 70.607143 | Y22: Mid Life (10 to 15 yr) | Z22: 35.035524 | AA22: =Z22*(33/30) -> 38.539076 | AG22: Mid Life (10 to 15 yr) | AH22: 19.599053 | AI22: =AH22*(33/30) -> 21.558958
Q23: Late Life (16 to 25 yr) | R23: 66.631252 | S23: =R23*(33/30) -> 73.294377 | T23: checked | U23: x | Y23: Late Life (16 to 25 yr) | Z23: 34.068908 | AA23: =Z23*(33/30) -> 37.475799 | AB23: checked | AC23: x | AG23: Late Life (16 to 25 yr) | AH23: 22.550618 | AI23: =AH23*(33/30) -> 24.80568 | AJ23: checked | AK23: x
P24: Longitudinal Stress Range at MidWall, MPa (Between Hot Oiling) | Q24: Early Life (1 to 9 yr) | R24: 235.15484 | S24: =R24*(33/30) -> 258.67033 | T24: checked | U24: x | X24: Longitudinal Stress Range at MidWall, MPa (Between Hot Oiling) | Y24: Early Life (1 to 15 yr) | Z24: 54.7664 | AA24: =Z24*(33/30) -> 60.24304 | AB24: checked | AC24: x | AF24: Longitudinal Stress Range at MidWall, MPa (Between Hot Oiling) | AG24: Early Life (1 to 9 yr) | AH24: 34.840507 | AI24: =AH24*(33/30) -> 38.324558 | AJ24: checked | AK24: x
Q25: Mid Life (10 to 15 yr) | R25: 166.43383 | S25: =R25*(33/30) -> 183.07721 | Y25: Mid Life (10 to 15 yr) | Z25: 50.820504 | AA25: =Z25*(33/30) -> 55.902554 | AG25: Mid Life (10 to 15 yr) | AH25: 29.879916 | AI25: =AH25*(33/30) -> 32.867908
Q26: Late Life (16 to 25 yr) | R26: 166.50995 | S26: =R26*(33/30) -> 183.16094 | T26: checked | U26: x | Y26: Late Life (16 to 25 yr) | Z26: 52.793888 | AA26: =Z26*(33/30) -> 58.073277 | AB26: checked | AC26: x | AG26: Late Life (16 to 25 yr) | AH26: 31.69288 | AI26: =AH26*(33/30) -> 34.862167 | AJ26: checked | AK26: x
P27: Longitudinal Stress Range at Midwall (Hydrotest), MPa | R27: 276.39056 | S27: =R27*(33/33) -> 276.39056 | T27: checked | U27: x | X27: Longitudinal Stress Range at Midwall (Hydrotest), MPa | Z27: 178.26163 | AA27: =Z27*(33/33) -> 178.26163 | AB27: checked | AC27: x | AF27: Longitudinal Stress Range at Midwall (Hydrotest), MPa | AH27: 170.5 | AI27: =AH27*(33/33) -> 170.5 | AJ27: checked | AK27: x
P28: Longitudinal Stress Range at Cap, MPa (FCD) | Q28: Early Life (1 to 9 yr) | R28: 269.57085 | S28: =R28*(33/30) -> 296.52793 | T28: checked | U28: x | X28: Longitudinal Stress Range at Cap, MPa (FCD) | Y28: Early Life (1 to 9 yr) | Z28: 86.15708 | AA28: =Z28*(33/30) -> 94.772788 | AB28: checked | AC28: x | AF28: Longitudinal Stress Range at Cap, MPa (FCD) | AG28: Early Life (1 to 9 yr) | AH28: 53.011371 | AI28: =AH28*(33/30) -> 58.312508 | AJ28: checked | AK28: x
Q29: Mid Life (10 to 15 yr) | R29: 257.64983 | S29: =R29*(33/30) -> 283.41481 | Y29: Mid Life (10 to 15 yr) | Z29: 88.073056 | AA29: =Z29*(33/30) -> 96.880362 | AG29: Mid Life (10 to 15 yr) | AH29: 52.62682 | AI29: =AH29*(33/30) -> 57.889502
Q30: Late Life (16 to 25 yr) | R30: 260.14455 | S30: =R30*(33/30) -> 286.159 | T30: checked | U30: x | Y30: Late Life (16 to 25 yr) | Z30: 89.07167 | AA30: =Z30*(33/30) -> 97.978837 | AB30: checked | AC30: x | AG30: Late Life (16 to 25 yr) | AH30: 52.614821 | AI30: =AH30*(33/30) -> 57.876303 | AJ30: checked | AK30: x
P31: Longitudinal Stress Range at Cap, MPa (PCD) | Q31: Early Life (1 to 9 yr) | R31: 100.43367 | S31: =R31*(33/30) -> 110.47703 | T31: checked | U31: x | X31: Longitudinal Stress Range at Cap, MPa (PCD) | Y31: Early Life (1 to 9 yr) | Z31: 49.822712 | AA31: =Z31*(33/30) -> 54.804983 | AB31: checked | AC31: x | AF31: Longitudinal Stress Range at Cap, MPa (PCD) | AG31: Early Life (1 to 9 yr) | AH31: 26.333564 | AI31: =AH31*(33/30) -> 28.96692 | AJ31: checked | AK31: x
Q32: Mid Life (10 to 15 yr) | R32: 72.389316 | S32: =R32*(33/30) -> 79.628248 | Y32: Mid Life (10 to 15 yr) | Z32: 37.478496 | AA32: =Z32*(33/30) -> 41.226346 | AG32: Mid Life (10 to 15 yr) | AH32: 19.991138 | AI32: =AH32*(33/30) -> 21.990252
Q33: Late Life (16 to 25 yr) | R33: 75.211976 | S33: =R33*(33/30) -> 82.733174 | T33: checked | U33: x | Y33: Late Life (16 to 25 yr) | Z33: 36.477764 | AA33: =Z33*(33/30) -> 40.12554 | AB33: checked | AC33: x | AG33: Late Life (16 to 25 yr) | AH33: 23.142534 | AI33: =AH33*(33/30) -> 25.456787 | AJ33: checked | AK33: x
P34: Longitudinal Stress Range at Cap, MPa (Between Hot Oiling) | Q34: Early Life (1 to 9 yr) | R34: 262.62108 | S34: =R34*(33/30) -> 288.88319 | T34: checked | U34: x | X34: Longitudinal Stress Range at Cap, MPa (Between Hot Oiling) | Y34: Early Life (1 to 9 yr) | Z34: 59.24906 | AA34: =Z34*(33/30) -> 65.173966 | AB34: checked | AC34: x | AF34: Longitudinal Stress Range at Cap, MPa (Between Hot Oiling) | AG34: Early Life (1 to 9 yr) | AH34: 34.867995 | AI34: =AH34*(33/30) -> 38.354795 | AJ34: checked | AK34: x
Q35: Mid Life (10 to 15 yr) | R35: 185.31456 | S35: =R35*(33/30) -> 203.84602 | Y35: Mid Life (10 to 15 yr) | Z35: 55.394804 | AA35: =Z35*(33/30) -> 60.934284 | AG35: Mid Life (10 to 15 yr) | AH35: 30.125788 | AI35: =AH35*(33/30) -> 33.138366
Q36: Late Life (16 to 25 yr) | R36: 185.45806 | S36: =R36*(33/30) -> 204.00387 | T36: checked | U36: x | Y36: Late Life (16 to 25 yr) | Z36: 57.381052 | AA36: =Z36*(33/30) -> 63.119157 | AB36: checked | AC36: x | AG36: Late Life (16 to 25 yr) | AH36: 31.94841 | AI36: =AH36*(33/30) -> 35.14325 | AJ36: checked | AK36: x
P37: Longitudinal Stress Range at CAP (Hydrotest), MPa | R37: 296.29962 | S37: =R37*(33/33) -> 296.29962 | T37: checked | U37: x | X37: Longitudinal Stress Range at CAP (Hydrotest), MPa | Z37: 186.89988 | AA37: =Z37*(33/33) -> 186.89988 | AB37: checked | AC37: x | AF37: Longitudinal Stress Range at CAP (Hydrotest), MPa | AH37: 176 | AI37: =AH37*(33/33) -> 176 | AJ37: checked | AK37: x
P40: Strain and Stress Ranges | R40: BE-HE | T40: BE-BE | U40: HE-BE | V40: Input for ECA | X40: Strain and Stress Ranges | Z40: BE-HE | AB40: BE-BE | AC40: HE-BE | AD40: Input for ECA | AF40: Strain and Stress Ranges | AH40: BE-HE | AJ40: BE-BE | AK40: HE-BE | AL40: Input for ECA
O41: 12in | P41: Max. Axial Mechanical Tensile Strain OD (Hydrotest) | W41: 12in | X41: Max. Axial Mechanical Tensile Strain OD (Hydrotest) | AE41: 12in | AF41: Max. Axial Mechanical Tensile Strain OD (Hydrotest)
O42: Sleeper | P42: Max. Axial Total Tensile Strain OD (Hydrotest) | W42: Structure | X42: Max. Axial Total Tensile Strain OD (Hydrotest) | AE42: Other | AF42: Max. Axial Total Tensile Strain OD (Hydrotest)
P43: Max. Axial Mechanical Tensile Strain ID (Hydrotest) | X43: Max. Axial Mechanical Tensile Strain ID (Hydrotest) | AF43: Max. Axial Mechanical Tensile Strain ID (Hydrotest)
...

Sheet BE-BE_P2toP1
P1: Strain and Stress Ranges | R1: BE-BE | X1: Strain and Stress Ranges | Z1: BE-BE | AF1: Strain and Stress Ranges | AH1: BE-BE
O2: 10in | P2: Max. Axial Mechanical Tensile Strain OD (Hydrotest) | W2: 10in | X2: Max. Axial Mechanical Tensile Strain OD (Hydrotest) | AE2: 10in | AF2: Max. Axial Mechanical Tensile Strain OD (Hydrotest)
O3: Sleeper | P3: Max. Axial Total Tensile Strain OD (Hydrotest) | W3: Structure | X3: Max. Axial Total Tensile Strain OD (Hydrotest) | AE3: Other | AF3: Max. Axial Total Tensile Strain OD (Hydrotest)
P4: Max. Axial Mechanical Tensile Strain ID (Hydrotest) | X4: Max. Axial Mechanical Tensile Strain ID (Hydrotest) | AF4: Max. Axial Mechanical Tensile Strain ID (Hydrotest)
P5: Max. Axial Total Tensile Strain ID (Hydrotest) | X5: Max. Axial Total Tensile Strain ID (Hydrotest) | AF5: Max. Axial Total Tensile Strain ID (Hydrotest)
P6: Max. Axial Mechanical Tensile Strain OD (Design) | X6: Max. Axial Mechanical Tensile Strain OD (Design) | AF6: Max. Axial Mechanical Tensile Strain OD (Design)
P7: Max. Axial Total Tensile Strain OD (Design) | X7: Max. Axial Total Tensile Strain OD (Design) | AF7: Max. Axial Total Tensile Strain OD (Design)
P8: Max. Axial Mechanical Tensile Strain ID (Design) | X8: Max. Axial Mechanical Tensile Strain ID (Design) | AF8: Max. Axial Mechanical Tensile Strain ID (Design)
P9: Max. Axial Total Tensile Strain ID (Design) | X9: Max. Axial Total Tensile Strain ID (Design) | AF9: Max. Axial Total Tensile Strain ID (Design)
P10: Max. Axial Mechanical Tensile Strain OD (Early Life) | X10: Max. Axial Mechanical Tensile Strain OD (Early Life) | AF10: Max. Axial Mechanical Tensile Strain OD (Early Life)
P11: Max. Axial Total Tensile Strain OD (Early Life) | X11: Max. Axial Total Tensile Strain OD (Early Life) | AF11: Max. Axial Total Tensile Strain OD (Early Life)
P12: Max. Axial Mechanical Tensile Strain ID (Early Life) | X12: Max. Axial Mechanical Tensile Strain ID (Early Life) | AF12: Max. Axial Mechanical Tensile Strain ID (Early Life)
P13: Max. Axial Total Tensile Strain ID (Early Life) | X13: Max. Axial Total Tensile Strain ID (Early Life) | AF13: Max. Axial Total Tensile Strain ID (Early Life)
P14: Max. Axial Mechanical Tensile Strain OD (Late Life) | X14: Max. Axial Mechanical Tensile Strain OD (Late Life) | AF14: Max. Axial Mechanical Tensile Strain OD (Late Life)
P15: Max. Axial Total Tensile Strain OD (Late Life) | X15: Max. Axial Total Tensile Strain OD (Late Life) | AF15: Max. Axial Total Tensile Strain OD (Late Life)
... P17: Max. Axial Total Tensile Strain ID (Late Life) | X17: Max. Axial Total Tensile Strain ID (Late Life) | AF17: Max. Axial Total Tensile Strain ID (Late Life)
P18: Longitudinal Stress Range at MidWall, MPa (FCD) | Q18: Early Life (1 to 9 yr) | R18: 237.92414 | S18: =R18*(33/30) -> 261.71655 | T18: checked | U18: x | X18: Longitudinal Stress Range at MidWall, MPa (FCD) | Y18: Early Life (1 to 9 yr) | Z18: 80.831584 | AA18: =Z18*(33/30) -> 88.914742 | AB18: checked | AC18: x | AF18: Longitudinal Stress Range at MidWall, MPa (FCD) | AG18: Early Life (1 to 9 yr) | AH18: 52.857608 | AI18: =AH18*(33/30) -> 58.143369 | AJ18: checked | AK18: x
Q19: Mid Life (10 to 15 yr) | R19: 228.96671 | S19: =R19*(33/30) -> 251.86338 | Y19: Mid Life (10 to 15 yr) | Z19: 82.687432 | AA19: =Z19*(33/30) -> 90.956175 | AG19: Mid Life (10 to 15 yr) | AH19: 52.49224 | AI19: =AH19*(33/30) -> 57.741464
Q20: Late Life (16 to 25 yr) | R20: 231.05079 | S20: =R20*(33/30) -> 254.15587 | T20: checked | U20: x | Y20: Late Life (16 to 25 yr) | Z20: 83.623908 | AA20: =Z20*(33/30) -> 91.986299 | AB20: checked | AC20: x | AG20: Late Life (16 to 25 yr) | AH20: 52.481115 | AI20: =AH20*(33/30) -> 57.729227 | AJ20: checked | AK20: x
P21: Longitudinal Stress Range at MidWall, MPa (PCD) | Q21: Early Life (1 to 9 yr) | R21: 88.525586 | S21: =R21*(33/30) -> 97.378145 | T21: checked | U21: x | X21: Longitudinal Stress Range at MidWall, MPa (PCD) | Y21: Early Life (1 to 9 yr) | Z21: 46.638424 | AA21: =Z21*(33/30) -> 51.302266 | AB21: checked | AC21: x | AF21: Longitudinal Stress Range at MidWall, MPa (PCD) | AG21: Early Life (1 to 9 yr) | AH21: 25.970224 | AI21: =AH21*(33/30) -> 28.567246 | AJ21: checked | AK21: x
Q22: Mid Life (10 to 15 yr) | R22: 64.188312 | S22: =R22*(33/30) -> 70.607143 | Y22: Mid Life (10 to 15 yr) | Z22: 35.035524 | AA22: =Z22*(33/30) -> 38.539076 | AG22: Mid Life (10 to 15 yr) | AH22: 19.599053 | AI22: =AH22*(33/30) -> 21.558958
Q23: Late Life (16 to 25 yr) | R23: 66.631252 | S23: =R23*(33/30) -> 73.294377 | T23: checked | U23: x | Y23: Late Life (16 to 25 yr) | Z23: 34.068908 | AA23: =Z23*(33/30) -> 37.475799 | AB23: checked | AC23: x | AG23: Late Life (16 to 25 yr) | AH23: 22.550618 | AI23: =AH23*(33/30) -> 24.80568 | AJ23: checked | AK23: x
P24: Longitudinal Stress Range at MidWall, MPa (Between Hot Oiling) | Q24: Early Life (1 to 9 yr) | R24: 235.15484 | S24: =R24*(33/30) -> 258.67033 | T24: checked | U24: x | X24: Longitudinal Stress Range at MidWall, MPa (Between Hot Oiling) | Y24: Early Life (1 to 15 yr) | Z24: 54.7664 | AA24: =Z24*(33/30) -> 60.24304 | AB24: checked | AC24: x | AF24: Longitudinal Stress Range at MidWall, MPa (Between Hot Oiling) | AG24: Early Life (1 to 9 yr) | AH24: 34.840507 | AI24: =AH24*(33/30) -> 38.324558 | AJ24: checked | AK24: x
Q25: Mid Life (10 to 15 yr) | R25: 166.43383 | S25: =R25*(33/30) -> 183.07721 | Y25: Mid Life (10 to 15 yr) | Z25: 50.820504 | AA25: =Z25*(33/30) -> 55.902554 | AG25: Mid Life (10 to 15 yr) | AH25: 29.879916 | AI25: =AH25*(33/30) -> 32.867908
Q26: Late Life (16 to 25 yr) | R26: 166.50995 | S26: =R26*(33/30) -> 183.16094 | T26: checked | U26: x | Y26: Late Life (16 to 25 yr) | Z26: 52.793888 | AA26: =Z26*(33/30) -> 58.073277 | AB26: checked | AC26: x | AG26: Late Life (16 to 25 yr) | AH26: 31.69288 | AI26: =AH26*(33/30) -> 34.862167 | AJ26: checked | AK26: x
P27: Longitudinal Stress Range at Midwall (Hydrotest), MPa | R27: 276.39056 | S27: =R27*(33/33) -> 276.39056 | T27: checked | U27: x | X27: Longitudinal Stress Range at Midwall (Hydrotest), MPa | Z27: 178.26163 | AA27: =Z27*(33/33) -> 178.26163 | AB27: checked | AC27: x | AF27: Longitudinal Stress Range at Midwall (Hydrotest), MPa | AH27: 170.5 | AI27: =AH27*(33/33) -> 170.5 | AJ27: checked | AK27: x
P28: Longitudinal Stress Range at Cap, MPa (FCD) | Q28: Early Life (1 to 9 yr) | R28: 269.57085 | S28: =R28*(33/30) -> 296.52793 | T28: checked | U28: x | X28: Longitudinal Stress Range at Cap, MPa (FCD) | Y28: Early Life (1 to 9 yr) | Z28: 86.15708 | AA28: =Z28*(33/30) -> 94.772788 | AB28: checked | AC28: x | AF28: Longitudinal Stress Range at Cap, MPa (FCD) | AG28: Early Life (1 to 9 yr) | AH28: 53.011371 | AI28: =AH28*(33/30) -> 58.312508 | AJ28: checked | AK28: x
Q29: Mid Life (10 to 15 yr) | R29: 257.64983 | S29: =R29*(33/30) -> 283.41481 | Y29: Mid Life (10 to 15 yr) | Z29: 88.073056 | AA29: =Z29*(33/30) -> 96.880362 | AG29: Mid Life (10 to 15 yr) | AH29: 52.62682 | AI29: =AH29*(33/30) -> 57.889502
Q30: Late Life (16 to 25 yr) | R30: 260.14455 | S30: =R30*(33/30) -> 286.159 | T30: checked | U30: x | Y30: Late Life (16 to 25 yr) | Z30: 89.07167 | AA30: =Z30*(33/30) -> 97.978837 | AB30: checked | AC30: x | AG30: Late Life (16 to 25 yr) | AH30: 52.614821 | AI30: =AH30*(33/30) -> 57.876303 | AJ30: checked | AK30: x
P31: Longitudinal Stress Range at Cap, MPa (PCD) | Q31: Early Life (1 to 9 yr) | R31: 100.43367 | S31: =R31*(33/30) -> 110.47703 | T31: checked | U31: x | X31: Longitudinal Stress Range at Cap, MPa (PCD) | Y31: Early Life (1 to 9 yr) | Z31: 49.822712 | AA31: =Z31*(33/30) -> 54.804983 | AB31: checked | AC31: x | AF31: Longitudinal Stress Range at Cap, MPa (PCD) | AG31: Early Life (1 to 9 yr) | AH31: 26.333564 | AI31: =AH31*(33/30) -> 28.96692 | AJ31: checked | AK31: x
Q32: Mid Life (10 to 15 yr) | R32: 72.389316 | S32: =R32*(33/30) -> 79.628248 | Y32: Mid Life (10 to 15 yr) | Z32: 37.478496 | AA32: =Z32*(33/30) -> 41.226346 | AG32: Mid Life (10 to 15 yr) | AH32: 19.991138 | AI32: =AH32*(33/30) -> 21.990252
Q33: Late Life (16 to 25 yr) | R33: 75.211976 | S33: =R33*(33/30) -> 82.733174 | T33: checked | U33: x | Y33: Late Life (16 to 25 yr) | Z33: 36.477764 | AA33: =Z33*(33/30) -> 40.12554 | AB33: checked | AC33: x | AG33: Late Life (16 to 25 yr) | AH33: 23.142534 | AI33: =AH33*(33/30) -> 25.456787 | AJ33: checked | AK33: x
P34: Longitudinal Stress Range at Cap, MPa (Between Hot Oiling) | Q34: Early Life (1 to 9 yr) | R34: 262.62108 | S34: =R34*(33/30) -> 288.88319 | T34: checked | U34: x | X34: Longitudinal Stress Range at Cap, MPa (Between Hot Oiling) | Y34: Early Life (1 to 9 yr) | Z34: 59.24906 | AA34: =Z34*(33/30) -> 65.173966 | AB34: checked | AC34: x | AF34: Longitudinal Stress Range at Cap, MPa (Between Hot Oiling) | AG34: Early Life (1 to 9 yr) | AH34: 34.867995 | AI34: =AH34*(33/30) -> 38.354795 | AJ34: checked | AK34: x
Q35: Mid Life (10 to 15 yr) | R35: 185.31456 | S35: =R35*(33/30) -> 203.84602 | Y35: Mid Life (10 to 15 yr) | Z35: 55.394804 | AA35: =Z35*(33/30) -> 60.934284 | AG35: Mid Life (10 to 15 yr) | AH35: 30.125788 | AI35: =AH35*(33/30) -> 33.138366
Q36: Late Life (16 to 25 yr) | R36: 185.45806 | S36: =R36*(33/30) -> 204.00387 | T36: checked | U36: x | Y36: Late Life (16 to 25 yr) | Z36: 57.381052 | AA36: =Z36*(33/30) -> 63.119157 | AB36: checked | AC36: x | AG36: Late Life (16 to 25 yr) | AH36: 31.94841 | AI36: =AH36*(33/30) -> 35.14325 | AJ36: checked | AK36: x
P37: Longitudinal Stress Range at CAP (Hydrotest), MPa | R37: 296.29962 | S37: =R37*(33/33) -> 296.29962 | T37: checked | U37: x | X37: Longitudinal Stress Range at CAP (Hydrotest), MPa | Z37: 186.89988 | AA37: =Z37*(33/33) -> 186.89988 | AB37: checked | AC37: x | AF37: Longitudinal Stress Range at CAP (Hydrotest), MPa | AH37: 176 | AI37: =AH37*(33/33) -> 176 | AJ37: checked | AK37: x
P40: Strain and Stress Ranges | R40: BE-HE | T40: BE-BE | U40: HE-BE | V40: Input for ECA | X40: Strain and Stress Ranges | Z40: BE-HE | AB40: BE-BE | AC40: HE-BE | AD40: Input for ECA | AF40: Strain and Stress Ranges | AH40: BE-HE | AJ40: BE-BE | AK40: HE-BE | AL40: Input for ECA
O41: 12in | P41: Max. Axial Mechanical Tensile Strain OD (Hydrotest) | W41: 12in | X41: Max. Axial Mechanical Tensile Strain OD (Hydrotest) | AE41: 12in | AF41: Max. Axial Mechanical Tensile Strain OD (Hydrotest)
O42: Sleeper | P42: Max. Axial Total Tensile Strain OD (Hydrotest) | W42: Structure | X42: Max. Axial Total Tensile Strain OD (Hydrotest) | AE42: Other | AF42: Max. Axial Total Tensile Strain OD (Hydrotest)
P43: Max. Axial Mechanical Tensile Strain ID (Hydrotest) | X43: Max. Axial Mechanical Tensile Strain ID (Hydrotest) | AF43: Max. Axial Mechanical Tensile Strain ID (Hydrotest)
...

Sheet HE-BEWalking
P1: Strain and Stress Ranges | R1: HE-BE | X1: Strain and Stress Ranges | Z1: HE-BE
O2: 10in | P2: Max. Axial Mechanical Tensile Strain OD (Hydrotest) | W2: 10in | X2: Max. Axial Mechanical Tensile Strain OD (Hydrotest)
O3: Non-Structural | P3: Max. Axial Total Tensile Strain OD (Hydrotest) | W3: Structure | X3: Max. Axial Total Tensile Strain OD (Hydrotest)
P4: Max. Axial Mechanical Tensile Strain ID (Hydrotest) | X4: Max. Axial Mechanical Tensile Strain ID (Hydrotest)
P5: Max. Axial Total Tensile Strain ID (Hydrotest) | X5: Max. Axial Total Tensile Strain ID (Hydrotest)
P6: Max. Axial Mechanical Tensile Strain OD (Design) | X6: Max. Axial Mechanical Tensile Strain OD (Design)
P7: Max. Axial Total Tensile Strain OD (Design) | X7: Max. Axial Total Tensile Strain OD (Design)
P8: Max. Axial Mechanical Tensile Strain ID (Design) | X8: Max. Axial Mechanical Tensile Strain ID (Design)
P9: Max. Axial Total Tensile Strain ID (Design) | X9: Max. Axial Total Tensile Strain ID (Design)
P10: Max. Axial Mechanical Tensile Strain OD (Early Life) | X10: Max. Axial Mechanical Tensile Strain OD (Early Life)
P11: Max. Axial Total Tensile Strain OD (Early Life) | X11: Max. Axial Total Tensile Strain OD (Early Life)
P12: Max. Axial Mechanical Tensile Strain ID (Early Life) | X12: Max. Axial Mechanical Tensile Strain ID (Early Life)
P13: Max. Axial Total Tensile Strain ID (Early Life) | X13: Max. Axial Total Tensile Strain ID (Early Life)
P14: Max. Axial Mechanical Tensile Strain OD (Late Life) | X14: Max. Axial Mechanical Tensile Strain OD (Late Life)
P15: Max. Axial Total Tensile Strain OD (Late Life) | X15: Max. Axial Total Tensile Strain OD (Late Life)
... P17: Max. Axial Total Tensile Strain ID (Late Life) | X17: Max. Axial Total Tensile Strain ID (Late Life)
P18: Longitudinal Stress Range at MidWall, MPa (FCD) | Q18: Early Life (1 to 15 yr) | S18: =R18*(33/30) -> 0 | T18: checked | U18: 222.9 | V18: r2tr1 | X18: Longitudinal Stress Range at MidWall, MPa (FCD) | Y18: Early Life (1 to 15 yr) | AA18: =Z18*(33/30) -> 0 | AB18: checked | AC18: 133.8 | AD18: r2tr1
Q19: Late Life (16 to 25 yr) | S19: =R19*(33/30) -> 0 | T19: checked | U19: 233 | V19: r2tr1 | Y19: Late Life (16 to 25 yr) | AA19: =Z19*(33/30) -> 0 | AB19: checked | AC19: 145.8 | AD19: r1tr2
P20: Longitudinal Stress Range at MidWall, MPa (PCD) | Q20: Early Life (1 to 15 yr) | S20: =R20*(33/30) -> 0 | T20: checked(RB) | U20: 40.7 | V20: R1tR2_rogue | X20: Longitudinal Stress Range at MidWall, MPa (PCD) | Y20: Early Life (1 to 15 yr) | AA20: =Z20*(33/30) -> 0 | AB20: checked | AC20: 56.4 | AD20: r2tr1
Q21: Late Life (16 to 25 yr) | S21: =R21*(33/30) -> 0 | T21: checked(RB) | U21: 39.2 | V21: R1tR2_rogue | Y21: Late Life (16 to 25 yr) | AA21: =Z21*(33/30) -> 0 | AB21: checked | AC21: 40.2 | AD21: r1tr2
P22: Longitudinal Stress Range at MidWall, MPa (Between Hot Oiling) | Q22: Early Life (1 to 15 yr) | S22: =R22*(33/30) -> 0 | T22: checked | U22: 97.9 | V22: R1tR2 | X22: Longitudinal Stress Range at MidWall, MPa (Between Hot Oiling) | Y22: Early Life (1 to 15 yr) | AA22: =Z22*(33/30) -> 0 | AB22: checked | AC22: 54 | AD22: r2tr1
Q23: Late Life (16 to 25 yr) | S23: =R23*(33/30) -> 0 | T23: checked | U23: 72.7 | V23: R1tR2 | Y23: Late Life (16 to 25 yr) | AA23: =Z23*(33/30) -> 0 | AB23: checked | AC23: 37.4 | AD23: r2tr1
P24: Longitudinal Stress Range at Midwall (Hydrotest), MPa | S24: =R24*(33/33) -> 0 | T24: checked | X24: Longitudinal Stress Range at Midwall (Hydrotest), MPa | AA24: =Z24*(33/33) -> 0 | AB24: checked
P25: Longitudinal Stress Range at Cap, MPa (FCD) | Q25: Early Life (1 to 15 yr) | S25: =R25*(33/30) -> 0 | T25: checked | U25: 250.7 | V25: r2tr1 | X25: Longitudinal Stress Range at Cap, MPa (FCD) | Y25: Early Life (1 to 15 yr) | AA25: =Z25*(33/30) -> 0 | AB25: checked | AC25: 140.7 | AD25: r2tr1
Q26: Late Life (16 to 25 yr) | S26: =R26*(33/30) -> 0 | T26: checked | U26: 261.3 | V26: r2tr1 | Y26: Late Life (16 to 25 yr) | AA26: =Z26*(33/30) -> 0 | AB26: checked | AC26: 153.9 | AD26: r1tr2
P27: Longitudinal Stress Range at Cap, MPa (PCD) | Q27: Early Life (1 to 15 yr) | S27: =R27*(33/30) -> 0 | T27: checked | U27: 44.8 | V27: R1tR2_rogue | X27: Longitudinal Stress Range at Cap, MPa (PCD) | Y27: Early Life (1 to 15 yr) | AA27: =Z27*(33/30) -> 0 | AB27: checked | AC27: 60 | AD27: r2tr1
Q28: Late Life (16 to 25 yr) | S28: =R28*(33/30) -> 0 | T28: checked | U28: 43 | V28: R1tR2_rogue | Y28: Late Life (16 to 25 yr) | AA28: =Z28*(33/30) -> 0 | AB28: checked | AC28: 43.1 | AD28: r1tr2
P29: Longitudinal Stress Range at Cap, MPa (Between Hot Oiling) | Q29: Early Life (1 to 15 yr) | S29: =R29*(33/30) -> 0 | T29: checked | U29: 110.2 | V29: R1tR2 | X29: Longitudinal Stress Range at Cap, MPa (Between Hot Oiling) | Y29: Early Life (1 to 15 yr) | AA29: =Z29*(33/30) -> 0 | AB29: checked | AC29: 58.8 | AD29: r2tr1
Q30: Late Life (16 to 25 yr) | S30: =R30*(33/30) -> 0 | T30: checked | U30: 81.8 | V30: R1tR2 | Y30: Late Life (16 to 25 yr) | AA30: =Z30*(33/30) -> 0 | AB30: checked | AC30: 40.5 | AD30: r2tr1
P31: Longitudinal Stress Range at CAP (Hydrotest), MPa | S31: =R31*(33/33) -> 0 | T31: checked | X31: Longitudinal Stress Range at CAP (Hydrotest), MPa | AA31: =Z31*(33/33) -> 0 | AB31: checked
P34: Strain and Stress Ranges | R34: BE-HE | S34: LE-BE | T34: BE-BE | U34: HE-BE | V34: Input for ECA | X34: Strain and Stress Ranges | Z34: BE-HE | AA34: LE-BE | AB34: BE-BE | AC34: HE-BE | AD34: Input for ECA
O35: 12in | P35: Max. Axial Mechanical Tensile Strain OD (Hydrotest) | W35: 12in | X35: Max. Axial Mechanical Tensile Strain OD (Hydrotest)
O36: Non-Structural | P36: Max. Axial Total Tensile Strain OD (Hydrotest) | W36: Structure | X36: Max. Axial Total Tensile Strain OD (Hydrotest)
P37: Max. Axial Mechanical Tensile Strain ID (Hydrotest) | X37: Max. Axial Mechanical Tensile Strain ID (Hydrotest)
P38: Max. Axial Total Tensile Strain ID (Hydrotest) | X38: Max. Axial Total Tensile Strain ID (Hydrotest)
P39: Max. Axial Mechanical Tensile Strain OD (Design) | X39: Max. Axial Mechanical Tensile Strain OD (Design)
P40: Max. Axial Total Tensile Strain OD (Design) | X40: Max. Axial Total Tensile Strain OD (Design)
P41: Max. Axial Mechanical Tensile Strain ID (Design) | X41: Max. Axial Mechanical Tensile Strain ID (Design)
P42: Max. Axial Total Tensile Strain ID (Design) | X42: Max. Axial Total Tensile Strain ID (Design)
P43: Max. Axial Mechanical Tensile Strain OD (Early Life) | X43: Max. Axial Mechanical Tensile Strain OD (Early Life)
...

Sheet HEBE_P1toP2
P1: Strain and Stress Ranges | R1: HE-BE | X1: Strain and Stress Ranges | Z1: HE-BE | AF1: Strain and Stress Ranges | AH1: HE-BE
O2: 10in | P2: Max. Axial Mechanical Tensile Strain OD (Hydrotest) | W2: 10in | X2: Max. Axial Mechanical Tensile Strain OD (Hydrotest) | AE2: 10in | AF2: Max. Axial Mechanical Tensile Strain OD (Hydrotest)
O3: Sleeper | P3: Max. Axial Total Tensile Strain OD (Hydrotest) | W3: Structure | X3: Max. Axial Total Tensile Strain OD (Hydrotest) | AE3: Other | AF3: Max. Axial Total Tensile Strain OD (Hydrotest)
P4: Max. Axial Mechanical Tensile Strain ID (Hydrotest) | X4: Max. Axial Mechanical Tensile Strain ID (Hydrotest) | AF4: Max. Axial Mechanical Tensile Strain ID (Hydrotest)
P5: Max. Axial Total Tensile Strain ID (Hydrotest) | X5: Max. Axial Total Tensile Strain ID (Hydrotest) | AF5: Max. Axial Total Tensile Strain ID (Hydrotest)
P6: Max. Axial Mechanical Tensile Strain OD (Design) | X6: Max. Axial Mechanical Tensile Strain OD (Design) | AF6: Max. Axial Mechanical Tensile Strain OD (Design)
P7: Max. Axial Total Tensile Strain OD (Design) | X7: Max. Axial Total Tensile Strain OD (Design) | AF7: Max. Axial Total Tensile Strain OD (Design)
P8: Max. Axial Mechanical Tensile Strain ID (Design) | X8: Max. Axial Mechanical Tensile Strain ID (Design) | AF8: Max. Axial Mechanical Tensile Strain ID (Design)
P9: Max. Axial Total Tensile Strain ID (Design) | X9: Max. Axial Total Tensile Strain ID (Design) | AF9: Max. Axial Total Tensile Strain ID (Design)
P10: Max. Axial Mechanical Tensile Strain OD (Early Life) | X10: Max. Axial Mechanical Tensile Strain OD (Early Life) | AF10: Max. Axial Mechanical Tensile Strain OD (Early Life)
P11: Max. Axial Total Tensile Strain OD (Early Life) | X11: Max. Axial Total Tensile Strain OD (Early Life) | AF11: Max. Axial Total Tensile Strain OD (Early Life)
P12: Max. Axial Mechanical Tensile Strain ID (Early Life) | X12: Max. Axial Mechanical Tensile Strain ID (Early Life) | AF12: Max. Axial Mechanical Tensile Strain ID (Early Life)
P13: Max. Axial Total Tensile Strain ID (Early Life) | X13: Max. Axial Total Tensile Strain ID (Early Life) | AF13: Max. Axial Total Tensile Strain ID (Early Life)
P14: Max. Axial Mechanical Tensile Strain OD (Late Life) | X14: Max. Axial Mechanical Tensile Strain OD (Late Life) | AF14: Max. Axial Mechanical Tensile Strain OD (Late Life)
P15: Max. Axial Total Tensile Strain OD (Late Life) | X15: Max. Axial Total Tensile Strain OD (Late Life) | AF15: Max. Axial Total Tensile Strain OD (Late Life)
... P17: Max. Axial Total Tensile Strain ID (Late Life) | X17: Max. Axial Total Tensile Strain ID (Late Life) | AF17: Max. Axial Total Tensile Strain ID (Late Life)
P18: Longitudinal Stress Range at MidWall, MPa (FCD) | Q18: Early Life (1 to 9 yr) | R18: 216.2 | S18: =R18*(33/30) -> 237.82 | T18: checked | U18: x | X18: Longitudinal Stress Range at MidWall, MPa (FCD) | Y18: Early Life (1 to 15 yr) | Z18: 81.690166 | AA18: =Z18*(33/30) -> 89.859183 | AB18: checked | AC18: x | AF18: Longitudinal Stress Range at MidWall, MPa (FCD) | AG18: Early Life (1 to 9 yr) | AH18: 67.1 | AI18: =AH18*(33/30) -> 73.81 | AJ18: checked | AK18: x
Q19: Mid Life (10 to 15 yr) | R19: 257.43662 | S19: =R19*(33/30) -> 283.18028 | Y19: Mid Life (10 to 15 yr) | Z19: 80.4867 | AA19: =Z19*(33/30) -> 88.53537 | AG19: Mid Life (10 to 15 yr) | AH19: 52.065058 | AI19: =AH19*(33/30) -> 57.271564
Q20: Late Life (16 to 25 yr) | R20: 257.75939 | S20: =R20*(33/30) -> 283.53533 | T20: checked | U20: x | Y20: Late Life (16 to 25 yr) | Z20: 80.939694 | AA20: =Z20*(33/30) -> 89.033663 | AB20: checked | AC20: x | AG20: Late Life (16 to 25 yr) | AH20: 52.011187 | AI20: =AH20*(33/30) -> 57.212306 | AJ20: checked | AK20: x
P21: Longitudinal Stress Range at MidWall, MPa (PCD) | Q21: Early Life (1 to 9 yr) | R21: 59.9 | S21: =R21*(33/30) -> 65.89 | T21: checked | U21: x | X21: Longitudinal Stress Range at MidWall, MPa (PCD) | Y21: Early Life (1 to 9 yr) | Z21: 46.638424 | AA21: =Z21*(33/30) -> 51.302266 | AB21: checked | AC21: x | AF21: Longitudinal Stress Range at MidWall, MPa (PCD) | AG21: Early Life (1 to 9 yr) | AH21: 25.641148 | AI21: =AH21*(33/30) -> 28.205263 | AJ21: checked | AK21: x
Q22: Mid Life (10 to 15 yr) | R22: 70.898492 | S22: =R22*(33/30) -> 77.988341 | Y22: Mid Life (10 to 15 yr) | Z22: 34.015404 | AA22: =Z22*(33/30) -> 37.416944 | AG22: Mid Life (10 to 15 yr) | AH22: 19.599053 | AI22: =AH22*(33/30) -> 21.558958
Q23: Late Life (16 to 25 yr) | R23: 71.097768 | S23: =R23*(33/30) -> 78.207545 | T23: checked | U23: x | Y23: Late Life (16 to 25 yr) | Z23: 36.35367 | AA23: =Z23*(33/30) -> 39.989037 | AB23: checked | AC23: x | AG23: Late Life (16 to 25 yr) | AH23: 22.550618 | AI23: =AH23*(33/30) -> 24.80568 | AJ23: checked | AK23: x
P24: Longitudinal Stress Range at MidWall, MPa (Between Hot Oiling) | Q24: Early Life (1 to 9 yr) | R24: 228.3 | S24: =R24*(33/30) -> 251.13 | T24: checked | U24: x | X24: Longitudinal Stress Range at MidWall, MPa (Between Hot Oiling) | Y24: Early Life (1 to 9 yr) | Z24: 50.283734 | AA24: =Z24*(33/30) -> 55.312107 | AB24: checked | AC24: x | AF24: Longitudinal Stress Range at MidWall, MPa (Between Hot Oiling) | AG24: Early Life (1 to 9 yr) | AH24: 34.799299 | AI24: =AH24*(33/30) -> 38.279229 | AJ24: checked | AK24: x
Q25: Mid Life (10 to 15 yr) | R25: 184.48921 | S25: =R25*(33/30) -> 202.93813 | Y25: Mid Life (10 to 15 yr) | Z25: 50.820504 | AA25: =Z25*(33/30) -> 55.902554 | AG25: Mid Life (10 to 15 yr) | AH25: 29.879916 | AI25: =AH25*(33/30) -> 32.867908 | AJ25: checked
Q26: Late Life (16 to 25 yr) | R26: 184.47419 | S26: =R26*(33/30) -> 202.9216 | T26: checked | U26: x | Y26: Late Life (16 to 25 yr) | Z26: 52.672068 | AA26: =Z26*(33/30) -> 57.939275 | AB26: checked | AC26: x | AG26: Late Life (16 to 25 yr) | AH26: 31.69288 | AI26: =AH26*(33/30) -> 34.862167 | AJ26: checked | AK26: x
P27: Longitudinal Stress Range at Midwall (Hydrotest), MPa | R27: 257.69429 | S27: =R27*(33/33) -> 257.69429 | T27: checked | U27: x | X27: Longitudinal Stress Range at Midwall (Hydrotest), MPa | Z27: 163.51738 | AA27: =Z27*(33/33) -> 163.51738 | AB27: checked | AC27: x | AF27: Longitudinal Stress Range at Midwall (Hydrotest), MPa | AH27: 142.3 | AI27: =AH27 -> 142.3 | AJ27: checked | AK27: x
P28: Longitudinal Stress Range at Cap, MPa (FCD) | Q28: Early Life (1 to 9 yr) | R28: 245.4 | S28: =R28*(33/30) -> 269.94 | T28: checked | U28: x | X28: Longitudinal Stress Range at Cap, MPa (FCD) | Y28: Early Life (1 to 9 yr) | Z28: 86.45202 | AA28: =Z28*(33/30) -> 95.097222 | AB28: checked | AC28: x | AF28: Longitudinal Stress Range at Cap, MPa (FCD) | AG28: Early Life (1 to 9 yr) | AH28: 67.8 | AI28: =AH28*(33/30) -> 74.58 | AJ28: checked | AK28: x
Q29: Mid Life (10 to 15 yr) | R29: 289.98902 | S29: =R29*(33/30) -> 318.98793 | Y29: Mid Life (10 to 15 yr) | Z29: 85.794078 | AA29: =Z29*(33/30) -> 94.373486 | AG29: Mid Life (10 to 15 yr) | AH29: 52.198681 | AI29: =AH29*(33/30) -> 57.418549
Q30: Late Life (16 to 25 yr) | R30: 290.70482 | S30: =R30*(33/30) -> 319.7753 | T30: checked | U30: x | Y30: Late Life (16 to 25 yr) | Z30: 86.289618 | AA30: =Z30*(33/30) -> 94.91858 | AB30: checked | AC30: x | AG30: Late Life (16 to 25 yr) | AH30: 52.14745 | AI30: =AH30*(33/30) -> 57.362195 | AJ30: checked | AK30: x
P31: Longitudinal Stress Range at Cap, MPa (PCD) | Q31: Early Life (1 to 9 yr) | R31: 66.9 | S31: =R31*(33/30) -> 73.59 | T31: checked | U31: x | X31: Longitudinal Stress Range at Cap, MPa (PCD) | Y31: Early Life (1 to 9 yr) | Z31: 43.454136 | AA31: =Z31*(33/30) -> 47.79955 | AB31: checked | AC31: x | AF31: Longitudinal Stress Range at Cap, MPa (PCD) | AG31: Early Life (1 to 9 yr) | AH31: 26.02629 | AI31: =AH31*(33/30) -> 28.628919 | AJ31: checked | AK31: x
Q32: Mid Life (10 to 15 yr) | R32: 79.988408 | S32: =R32*(33/30) -> 87.987249 | Y32: Mid Life (10 to 15 yr) | Z32: 36.454376 | AA32: =Z32*(33/30) -> 40.099814 | AG32: Mid Life (10 to 15 yr) | AH32: 19.991138 | AI32: =AH32*(33/30) -> 21.990252
Q33: Late Life (16 to 25 yr) | R33: 80.254896 | S33: =R33*(33/30) -> 88.280386 | T33: checked | U33: x | Y33: Late Life (16 to 25 yr) | Z33: 40.341032 | AA33: =Z33*(33/30) -> 44.375135 | AB33: checked | AC33: x | AG33: Late Life (16 to 25 yr) | AH33: 23.142534 | AI33: =AH33*(33/30) -> 25.456787 | AJ33: checked | AK33: x
P34: Longitudinal Stress Range at Cap, MPa (Between Hot Oiling) | Q34: Early Life (1 to 9 yr) | R34: 254.8 | S34: =R34*(33/30) -> 280.28 | T34: checked | U34: x | X34: Longitudinal Stress Range at Cap, MPa (Between Hot Oiling) | Y34: Early Life (1 to 9 yr) | Z34: 59.24906 | AA34: =Z34*(33/30) -> 65.173966 | AB34: checked | AC34: x | AF34: Longitudinal Stress Range at Cap, MPa (Between Hot Oiling) | AG34: Early Life (1 to 9 yr) | AH34: 34.769156 | AI34: =AH34*(33/30) -> 38.246072 | AJ34: checked | AK34: x
Q35: Mid Life (10 to 15 yr) | R35: 205.84825 | S35: =R35*(33/30) -> 226.43308 | Y35: Mid Life (10 to 15 yr) | Z35: 55.394804 | AA35: =Z35*(33/30) -> 60.934284 | AG35: Mid Life (10 to 15 yr) | AH35: 30.125788 | AI35: =AH35*(33/30) -> 33.138366
Q36: Late Life (16 to 25 yr) | R36: 205.86737 | S36: =R36*(33/30) -> 226.45411 | T36: checked | U36: x | Y36: Late Life (16 to 25 yr) | Z36: 57.28958 | AA36: =Z36*(33/30) -> 63.018538 | AB36: checked | AC36: x | AG36: Late Life (16 to 25 yr) | AH36: 31.94841 | AI36: =AH36*(33/30) -> 35.14325 | AJ36: checked | AK36: x
P37: Longitudinal Stress Range at CAP (Hydrotest), MPa | R37: 277.22238 | S37: =R37*(33/33) -> 277.22238 | T37: checked | U37: x | X37: Longitudinal Stress Range at CAP (Hydrotest), MPa | Z37: 172.1276 | AA37: =Z37*(33/33) -> 172.1276 | AB37: checked | AC37: x | AF37: Longitudinal Stress Range at CAP (Hydrotest), MPa | AH37: 146.1 | AI37: =AH37*(33/33) -> 146.1 | AJ37: checked | AK37: x
P40: Strain and Stress Ranges | R40: HE-BE | T40: BE-BE | U40: HE-BE | V40: Input for ECA | X40: Strain and Stress Ranges | Z40: HE-BE | AB40: BE-BE | AC40: HE-BE | AD40: Input for ECA | AF40: Strain and Stress Ranges | AH40: HE-BE | AJ40: BE-BE | AK40: HE-BE | AL40: Input for ECA
O41: 12in | P41: Max. Axial Mechanical Tensile Strain OD (Hydrotest) | W41: 12in | X41: Max. Axial Mechanical Tensile Strain OD (Hydrotest) | AE41: 12in | AF41: Max. Axial Mechanical Tensile Strain OD (Hydrotest)
O42: Sleeper | P42: Max. Axial Total Tensile Strain OD (Hydrotest) | W42: Structure | X42: Max. Axial Total Tensile Strain OD (Hydrotest) | AE42: Other | AF42: Max. Axial Total Tensile Strain OD (Hydrotest)
P43: Max. Axial Mechanical Tensile Strain ID (Hydrotest) | X43: Max. Axial Mechanical Tensile Strain ID (Hydrotest) | AF43: Max. Axial Mechanical Tensile Strain ID (Hydrotest)
...

Sheet HEBE_P2toP1
P1: Strain and Stress Ranges | R1: HE-BE | X1: Strain and Stress Ranges | Z1: HE-BE | AF1: Strain and Stress Ranges | AH1: HE-BE
O2: 10in | P2: Max. Axial Mechanical Tensile Strain OD (Hydrotest) | W2: 10in | X2: Max. Axial Mechanical Tensile Strain OD (Hydrotest) | AE2: 10in | AF2: Max. Axial Mechanical Tensile Strain OD (Hydrotest)
O3: Sleeper | P3: Max. Axial Total Tensile Strain OD (Hydrotest) | W3: Structure | X3: Max. Axial Total Tensile Strain OD (Hydrotest) | AE3: Other | AF3: Max. Axial Total Tensile Strain OD (Hydrotest)
P4: Max. Axial Mechanical Tensile Strain ID (Hydrotest) | X4: Max. Axial Mechanical Tensile Strain ID (Hydrotest) | AF4: Max. Axial Mechanical Tensile Strain ID (Hydrotest)
P5: Max. Axial Total Tensile Strain ID (Hydrotest) | X5: Max. Axial Total Tensile Strain ID (Hydrotest) | AF5: Max. Axial Total Tensile Strain ID (Hydrotest)
P6: Max. Axial Mechanical Tensile Strain OD (Design) | X6: Max. Axial Mechanical Tensile Strain OD (Design) | AF6: Max. Axial Mechanical Tensile Strain OD (Design)
P7: Max. Axial Total Tensile Strain OD (Design) | X7: Max. Axial Total Tensile Strain OD (Design) | AF7: Max. Axial Total Tensile Strain OD (Design)
